<?xml version="1.0"?>
<robot xmlns:xacro="http://www.ros.org/wiki/xacro" >

    <material name="white">
        <color rgba="1.0 1.0 1.0 1.0"/>
    </material>
    
    <material name="orange">
        <color rgba="1.0 0.3 0.1 1.0"/>
    </material>
    
    <material name="blue">
        <color rgba="0.0 0.0 1.0 1.0"/>    
    </material>
    
    <material name="black">
        <color rgba="0.0 0.0 0.0 1.0"/>
    </material>

    <!-- base link-->
    <link name="base_link">
        
    </link>

    <joint name="chassis_joint" type="fixed">
        <parent link="base_link"/>
        <child link="chassis"/>
        <origin xyz="0.0 0.0 0.0"/>
    </joint>
<!-- chassis link-->
    <link name="chassis">
        <visual>
            <origin xyz="0.0 0.0 0.075"/>
            <geometry>
                <box size="0.4 0.3 0.15"/>
            </geometry>
            <material name="white"/>
        </visual>
    </link>

<!--left front wheel-->

<joint name="left_front_wheel_joint" type="continuous">
    <parent link="base_link"/>
    <child link="left_front_wheel"/>
    <origin xyz="0.125 0.175 0.0" rpy="-${pi/2} 0.0 0.0"/>
    <axis xyz="0.0 0.0 1.0"/>
</joint>

<link name="left_front_wheel">
    <visual>
        <geometry>
            <cylinder radius="0.075" length="0.04"/>
        </geometry>
        <material name="blue"/>
    </visual>
</link>
<!--right front wheel-->

<joint name="right_front_wheel_joint" type="continuous">
    <parent link="base_link"/>
    <child link="right_front_wheel"/>
    <origin xyz="0.125 -0.175 0.0" rpy="${pi/2} 0.0 0.0"/>
    <axis xyz="0.0 0.0 1.0"/>
</joint>

<link name="right_front_wheel">
    <visual>
        <geometry>
            <cylinder radius="0.075" length="0.04"/>
        </geometry>
        <material name="blue"/>
    </visual>
</link>

<!--left back wheel-->

<joint name="left_back_wheel_joint" type="continuous">
    <parent link="base_link"/>
    <child link="left_back_wheel"/>
    <origin xyz="-0.125 0.175 0.0" rpy="-${pi/2} 0.0 0.0"/>
    <axis xyz="0.0 0.0 1.0"/>
</joint>

<link name="left_back_wheel">
    <visual>
        <geometry>
            <cylinder radius="0.075" length="0.04"/>
        </geometry>
        <material name="blue"/>
    </visual>
</link>
<!--right back wheel-->

<joint name="right_back_wheel_joint" type="continuous">
    <parent link="base_link"/>
    <child link="right_back_wheel"/>
    <origin xyz="-0.125 -0.175 0.0" rpy="${pi/2} 0.0 0.0"/>
    <axis xyz="0.0 0.0 1.0"/>
</joint>

<link name="right_back_wheel">
    <visual>
        <geometry>
            <cylinder radius="0.075" length="0.04"/>
        </geometry>
        <material name="blue"/>
    </visual>
</link>
</robot>