<sdf version='1.7'>
  <world name='default'>
    <light name='sun' type='directional'>
      <cast_shadows>1</cast_shadows>
      <pose>0 0 10 0 -0 0</pose>
      <diffuse>0.8 0.8 0.8 1</diffuse>
      <specular>0.2 0.2 0.2 1</specular>
      <attenuation>
        <range>1000</range>
        <constant>0.9</constant>
        <linear>0.01</linear>
        <quadratic>0.001</quadratic>
      </attenuation>
      <direction>-0.5 0.1 -0.9</direction>
      <spot>
        <inner_angle>0</inner_angle>
        <outer_angle>0</outer_angle>
        <falloff>0</falloff>
      </spot>
    </light>
    <model name='ground_plane'>
      <static>1</static>
      <link name='link'>
        <collision name='collision'>
          <geometry>
            <plane>
              <normal>0 0 1</normal>
              <size>100 100</size>
            </plane>
          </geometry>
          <surface>
            <contact>
              <collide_bitmask>65535</collide_bitmask>
              <ode/>
            </contact>
            <friction>
              <ode>
                <mu>100</mu>
                <mu2>50</mu2>
              </ode>
              <torsional>
                <ode/>
              </torsional>
            </friction>
            <bounce/>
          </surface>
          <max_contacts>10</max_contacts>
        </collision>
        <visual name='visual'>
          <cast_shadows>0</cast_shadows>
          <geometry>
            <plane>
              <normal>0 0 1</normal>
              <size>100 100</size>
            </plane>
          </geometry>
          <material>
            <script>
              <uri>file://media/materials/scripts/gazebo.material</uri>
              <name>Gazebo/Grey</name>
            </script>
          </material>
        </visual>
        <self_collide>0</self_collide>
        <enable_wind>0</enable_wind>
        <kinematic>0</kinematic>
      </link>
    </model>
    <gravity>0 0 -9.8</gravity>
    <magnetic_field>6e-06 2.3e-05 -4.2e-05</magnetic_field>
    <atmosphere type='adiabatic'/>
    <physics type='ode'>
      <max_step_size>0.001</max_step_size>
      <real_time_factor>1</real_time_factor>
      <real_time_update_rate>1000</real_time_update_rate>
    </physics>
    <scene>
      <ambient>0.4 0.4 0.4 1</ambient>
      <background>0.7 0.7 0.7 1</background>
      <shadows>1</shadows>
    </scene>
    <audio>
      <device>default</device>
    </audio>
    <wind/>
    <spherical_coordinates>
      <surface_model>EARTH_WGS84</surface_model>
      <latitude_deg>0</latitude_deg>
      <longitude_deg>0</longitude_deg>
      <elevation>0</elevation>
      <heading_deg>0</heading_deg>
    </spherical_coordinates>
    <model name='ambulance'>
      <static>1</static>
      <link name='link'>
        <collision name='collision'>
          <geometry>
            <mesh>
              <scale>0.0254 0.0254 0.0254</scale>
              <uri>model://ambulance/meshes/ambulance.obj</uri>
            </mesh>
          </geometry>
          <max_contacts>10</max_contacts>
          <surface>
            <contact>
              <ode/>
            </contact>
            <bounce/>
            <friction>
              <torsional>
                <ode/>
              </torsional>
              <ode/>
            </friction>
          </surface>
        </collision>
        <visual name='visual'>
          <geometry>
            <mesh>
              <scale>0.0254 0.0254 0.0254</scale>
              <uri>model://ambulance/meshes/ambulance.obj</uri>
            </mesh>
          </geometry>
        </visual>
        <self_collide>0</self_collide>
        <enable_wind>0</enable_wind>
        <kinematic>0</kinematic>
      </link>
      <pose>6.51401 4.62614 0 0 -0 0</pose>
    </model>
    <model name='cart_soft_suspension'>
      <link name='chassis'>
        <pose>0 0 0.15 0 -0 0</pose>
        <inertial>
          <pose>0.1 0 0 0 -0 0</pose>
          <mass>10</mass>
          <inertia>
            <ixx>0.216667</ixx>
            <iyy>0.841667</iyy>
            <izz>1.04167</izz>
            <ixy>0</ixy>
            <ixz>0</ixz>
            <iyz>0</iyz>
          </inertia>
        </inertial>
        <collision name='collision'>
          <geometry>
            <box>
              <size>1 0.5 0.1</size>
            </box>
          </geometry>
          <max_contacts>10</max_contacts>
          <surface>
            <contact>
              <ode/>
            </contact>
            <bounce/>
            <friction>
              <torsional>
                <ode/>
              </torsional>
              <ode/>
            </friction>
          </surface>
        </collision>
        <visual name='visual'>
          <geometry>
            <box>
              <size>1 0.5 0.1</size>
            </box>
          </geometry>
          <material>
            <script>
              <uri>file://media/materials/scripts/gazebo.material</uri>
              <name>Gazebo/Grey</name>
            </script>
          </material>
        </visual>
        <self_collide>0</self_collide>
        <enable_wind>0</enable_wind>
        <kinematic>0</kinematic>
      </link>
      <link name='susp_front_right'>
        <pose>0.5 -0.298 0.15 0 -0 0</pose>
        <inertial>
          <mass>0.5</mass>
          <inertia>
            <ixx>0.000208333</ixx>
            <iyy>0.000208333</iyy>
            <izz>0.000208333</izz>
            <ixy>0</ixy>
            <ixz>0</ixz>
            <iyz>0</iyz>
          </inertia>
          <pose>0 0 0 0 -0 0</pose>
        </inertial>
        <collision name='collision'>
          <geometry>
            <box>
              <size>0.05 0.05 0.05</size>
            </box>
          </geometry>
          <max_contacts>10</max_contacts>
          <surface>
            <contact>
              <ode/>
            </contact>
            <bounce/>
            <friction>
              <torsional>
                <ode/>
              </torsional>
              <ode/>
            </friction>
          </surface>
        </collision>
        <visual name='visual'>
          <geometry>
            <box>
              <size>0.05 0.05 0.05</size>
            </box>
          </geometry>
          <material>
            <script>
              <uri>file://media/materials/scripts/gazebo.material</uri>
              <name>Gazebo/Black</name>
            </script>
          </material>
        </visual>
        <self_collide>0</self_collide>
        <enable_wind>0</enable_wind>
        <kinematic>0</kinematic>
      </link>
      <joint name='susp_front_right_prismatic' type='prismatic'>
        <parent>chassis</parent>
        <child>susp_front_right</child>
        <axis>
          <xyz>0 0 -1</xyz>
          <limit>
            <lower>-0.0375</lower>
            <upper>0.0375</upper>
          </limit>
          <dynamics>
            <damping>100</damping>
            <spring_stiffness>2500</spring_stiffness>
            <spring_reference>0.05</spring_reference>
          </dynamics>
        </axis>
        <physics>
          <ode>
            <implicit_spring_damper>1</implicit_spring_damper>
            <limit>
              <cfm>0</cfm>
              <erp>0.2</erp>
            </limit>
          </ode>
        </physics>
      </joint>
      <link name='wheel_front_right'>
        <pose>0.5 -0.298 0.15 -1.5708 0 0</pose>
        <inertial>
          <mass>0.5</mass>
          <inertia>
            <ixx>0.00307917</ixx>
            <iyy>0.00307917</iyy>
            <izz>0.005625</izz>
            <ixy>0</ixy>
            <ixz>0</ixz>
            <iyz>0</iyz>
          </inertia>
          <pose>0 0 0 0 -0 0</pose>
        </inertial>
        <collision name='collision'>
          <geometry>
            <cylinder>
              <radius>0.15</radius>
              <length>0.08</length>
            </cylinder>
          </geometry>
          <max_contacts>10</max_contacts>
          <surface>
            <contact>
              <ode/>
            </contact>
            <bounce/>
            <friction>
              <torsional>
                <ode/>
              </torsional>
              <ode/>
            </friction>
          </surface>
        </collision>
        <visual name='visual'>
          <geometry>
            <cylinder>
              <radius>0.15</radius>
              <length>0.08</length>
            </cylinder>
          </geometry>
          <material>
            <script>
              <uri>file://media/materials/scripts/gazebo.material</uri>
              <name>Gazebo/Black</name>
            </script>
          </material>
        </visual>
        <self_collide>0</self_collide>
        <enable_wind>0</enable_wind>
        <kinematic>0</kinematic>
      </link>
      <joint name='wheel_front_right_spin' type='revolute'>
        <parent>susp_front_right</parent>
        <child>wheel_front_right</child>
        <axis>
          <xyz>0 0 1</xyz>
          <limit>
            <lower>-1e+16</lower>
            <upper>1e+16</upper>
          </limit>
          <dynamics>
            <spring_reference>0</spring_reference>
            <spring_stiffness>0</spring_stiffness>
          </dynamics>
        </axis>
      </joint>
      <link name='susp_front_left'>
        <pose>0.5 0.298 0.15 0 -0 0</pose>
        <inertial>
          <mass>0.5</mass>
          <inertia>
            <ixx>0.000208333</ixx>
            <iyy>0.000208333</iyy>
            <izz>0.000208333</izz>
            <ixy>0</ixy>
            <ixz>0</ixz>
            <iyz>0</iyz>
          </inertia>
          <pose>0 0 0 0 -0 0</pose>
        </inertial>
        <collision name='collision'>
          <geometry>
            <box>
              <size>0.05 0.05 0.05</size>
            </box>
          </geometry>
          <max_contacts>10</max_contacts>
          <surface>
            <contact>
              <ode/>
            </contact>
            <bounce/>
            <friction>
              <torsional>
                <ode/>
              </torsional>
              <ode/>
            </friction>
          </surface>
        </collision>
        <visual name='visual'>
          <geometry>
            <box>
              <size>0.05 0.05 0.05</size>
            </box>
          </geometry>
          <material>
            <script>
              <uri>file://media/materials/scripts/gazebo.material</uri>
              <name>Gazebo/Black</name>
            </script>
          </material>
        </visual>
        <self_collide>0</self_collide>
        <enable_wind>0</enable_wind>
        <kinematic>0</kinematic>
      </link>
      <joint name='susp_front_left_prismatic' type='prismatic'>
        <parent>chassis</parent>
        <child>susp_front_left</child>
        <axis>
          <xyz>0 0 -1</xyz>
          <limit>
            <lower>-0.0375</lower>
            <upper>0.0375</upper>
          </limit>
          <dynamics>
            <damping>100</damping>
            <spring_stiffness>2500</spring_stiffness>
            <spring_reference>0.05</spring_reference>
          </dynamics>
        </axis>
        <physics>
          <ode>
            <implicit_spring_damper>1</implicit_spring_damper>
            <limit>
              <cfm>0</cfm>
              <erp>0.2</erp>
            </limit>
          </ode>
        </physics>
      </joint>
      <link name='wheel_front_left'>
        <pose>0.5 0.298 0.15 -1.5708 0 0</pose>
        <inertial>
          <mass>0.5</mass>
          <inertia>
            <ixx>0.00307917</ixx>
            <iyy>0.00307917</iyy>
            <izz>0.005625</izz>
            <ixy>0</ixy>
            <ixz>0</ixz>
            <iyz>0</iyz>
          </inertia>
          <pose>0 0 0 0 -0 0</pose>
        </inertial>
        <collision name='collision'>
          <geometry>
            <cylinder>
              <radius>0.15</radius>
              <length>0.08</length>
            </cylinder>
          </geometry>
          <max_contacts>10</max_contacts>
          <surface>
            <contact>
              <ode/>
            </contact>
            <bounce/>
            <friction>
              <torsional>
                <ode/>
              </torsional>
              <ode/>
            </friction>
          </surface>
        </collision>
        <visual name='visual'>
          <geometry>
            <cylinder>
              <radius>0.15</radius>
              <length>0.08</length>
            </cylinder>
          </geometry>
          <material>
            <script>
              <uri>file://media/materials/scripts/gazebo.material</uri>
              <name>Gazebo/Black</name>
            </script>
          </material>
        </visual>
        <self_collide>0</self_collide>
        <enable_wind>0</enable_wind>
        <kinematic>0</kinematic>
      </link>
      <joint name='wheel_front_left_spin' type='revolute'>
        <parent>susp_front_left</parent>
        <child>wheel_front_left</child>
        <axis>
          <xyz>0 0 1</xyz>
          <limit>
            <lower>-1e+16</lower>
            <upper>1e+16</upper>
          </limit>
          <dynamics>
            <spring_reference>0</spring_reference>
            <spring_stiffness>0</spring_stiffness>
          </dynamics>
        </axis>
      </joint>
      <link name='susp_rear_right'>
        <pose>-0.5 -0.298 0.15 0 -0 0</pose>
        <inertial>
          <mass>0.5</mass>
          <inertia>
            <ixx>0.000208333</ixx>
            <iyy>0.000208333</iyy>
            <izz>0.000208333</izz>
            <ixy>0</ixy>
            <ixz>0</ixz>
            <iyz>0</iyz>
          </inertia>
          <pose>0 0 0 0 -0 0</pose>
        </inertial>
        <collision name='collision'>
          <geometry>
            <box>
              <size>0.05 0.05 0.05</size>
            </box>
          </geometry>
          <max_contacts>10</max_contacts>
          <surface>
            <contact>
              <ode/>
            </contact>
            <bounce/>
            <friction>
              <torsional>
                <ode/>
              </torsional>
              <ode/>
            </friction>
          </surface>
        </collision>
        <visual name='visual'>
          <geometry>
            <box>
              <size>0.05 0.05 0.05</size>
            </box>
          </geometry>
          <material>
            <script>
              <uri>file://media/materials/scripts/gazebo.material</uri>
              <name>Gazebo/Black</name>
            </script>
          </material>
        </visual>
        <self_collide>0</self_collide>
        <enable_wind>0</enable_wind>
        <kinematic>0</kinematic>
      </link>
      <joint name='susp_rear_right_prismatic' type='prismatic'>
        <parent>chassis</parent>
        <child>susp_rear_right</child>
        <axis>
          <xyz>0 0 -1</xyz>
          <limit>
            <lower>-0.0375</lower>
            <upper>0.0375</upper>
          </limit>
          <dynamics>
            <damping>100</damping>
            <spring_stiffness>2500</spring_stiffness>
            <spring_reference>0.05</spring_reference>
          </dynamics>
        </axis>
        <physics>
          <ode>
            <implicit_spring_damper>1</implicit_spring_damper>
            <limit>
              <cfm>0</cfm>
              <erp>0.2</erp>
            </limit>
          </ode>
        </physics>
      </joint>
      <link name='wheel_rear_right'>
        <pose>-0.5 -0.298 0.15 -1.5708 0 0</pose>
        <inertial>
          <mass>0.5</mass>
          <inertia>
            <ixx>0.00307917</ixx>
            <iyy>0.00307917</iyy>
            <izz>0.005625</izz>
            <ixy>0</ixy>
            <ixz>0</ixz>
            <iyz>0</iyz>
          </inertia>
          <pose>0 0 0 0 -0 0</pose>
        </inertial>
        <collision name='collision'>
          <geometry>
            <cylinder>
              <radius>0.15</radius>
              <length>0.08</length>
            </cylinder>
          </geometry>
          <max_contacts>10</max_contacts>
          <surface>
            <contact>
              <ode/>
            </contact>
            <bounce/>
            <friction>
              <torsional>
                <ode/>
              </torsional>
              <ode/>
            </friction>
          </surface>
        </collision>
        <visual name='visual'>
          <geometry>
            <cylinder>
              <radius>0.15</radius>
              <length>0.08</length>
            </cylinder>
          </geometry>
          <material>
            <script>
              <uri>file://media/materials/scripts/gazebo.material</uri>
              <name>Gazebo/Black</name>
            </script>
          </material>
        </visual>
        <self_collide>0</self_collide>
        <enable_wind>0</enable_wind>
        <kinematic>0</kinematic>
      </link>
      <joint name='wheel_rear_right_spin' type='revolute'>
        <parent>susp_rear_right</parent>
        <child>wheel_rear_right</child>
        <axis>
          <xyz>0 0 1</xyz>
          <limit>
            <lower>-1e+16</lower>
            <upper>1e+16</upper>
          </limit>
          <dynamics>
            <spring_reference>0</spring_reference>
            <spring_stiffness>0</spring_stiffness>
          </dynamics>
        </axis>
      </joint>
      <link name='susp_rear_left'>
        <pose>-0.5 0.298 0.15 0 -0 0</pose>
        <inertial>
          <mass>0.5</mass>
          <inertia>
            <ixx>0.000208333</ixx>
            <iyy>0.000208333</iyy>
            <izz>0.000208333</izz>
            <ixy>0</ixy>
            <ixz>0</ixz>
            <iyz>0</iyz>
          </inertia>
          <pose>0 0 0 0 -0 0</pose>
        </inertial>
        <collision name='collision'>
          <geometry>
            <box>
              <size>0.05 0.05 0.05</size>
            </box>
          </geometry>
          <max_contacts>10</max_contacts>
          <surface>
            <contact>
              <ode/>
            </contact>
            <bounce/>
            <friction>
              <torsional>
                <ode/>
              </torsional>
              <ode/>
            </friction>
          </surface>
        </collision>
        <visual name='visual'>
          <geometry>
            <box>
              <size>0.05 0.05 0.05</size>
            </box>
          </geometry>
          <material>
            <script>
              <uri>file://media/materials/scripts/gazebo.material</uri>
              <name>Gazebo/Black</name>
            </script>
          </material>
        </visual>
        <self_collide>0</self_collide>
        <enable_wind>0</enable_wind>
        <kinematic>0</kinematic>
      </link>
      <joint name='susp_rear_left_prismatic' type='prismatic'>
        <parent>chassis</parent>
        <child>susp_rear_left</child>
        <axis>
          <xyz>0 0 -1</xyz>
          <limit>
            <lower>-0.0375</lower>
            <upper>0.0375</upper>
          </limit>
          <dynamics>
            <damping>100</damping>
            <spring_stiffness>2500</spring_stiffness>
            <spring_reference>0.05</spring_reference>
          </dynamics>
        </axis>
        <physics>
          <ode>
            <implicit_spring_damper>1</implicit_spring_damper>
            <limit>
              <cfm>0</cfm>
              <erp>0.2</erp>
            </limit>
          </ode>
        </physics>
      </joint>
      <link name='wheel_rear_left'>
        <pose>-0.5 0.298 0.15 -1.5708 0 0</pose>
        <inertial>
          <mass>0.5</mass>
          <inertia>
            <ixx>0.00307917</ixx>
            <iyy>0.00307917</iyy>
            <izz>0.005625</izz>
            <ixy>0</ixy>
            <ixz>0</ixz>
            <iyz>0</iyz>
          </inertia>
          <pose>0 0 0 0 -0 0</pose>
        </inertial>
        <collision name='collision'>
          <geometry>
            <cylinder>
              <radius>0.15</radius>
              <length>0.08</length>
            </cylinder>
          </geometry>
          <max_contacts>10</max_contacts>
          <surface>
            <contact>
              <ode/>
            </contact>
            <bounce/>
            <friction>
              <torsional>
                <ode/>
              </torsional>
              <ode/>
            </friction>
          </surface>
        </collision>
        <visual name='visual'>
          <geometry>
            <cylinder>
              <radius>0.15</radius>
              <length>0.08</length>
            </cylinder>
          </geometry>
          <material>
            <script>
              <uri>file://media/materials/scripts/gazebo.material</uri>
              <name>Gazebo/Black</name>
            </script>
          </material>
        </visual>
        <self_collide>0</self_collide>
        <enable_wind>0</enable_wind>
        <kinematic>0</kinematic>
      </link>
      <joint name='wheel_rear_left_spin' type='revolute'>
        <parent>susp_rear_left</parent>
        <child>wheel_rear_left</child>
        <axis>
          <xyz>0 0 1</xyz>
          <limit>
            <lower>-1e+16</lower>
            <upper>1e+16</upper>
          </limit>
          <dynamics>
            <spring_reference>0</spring_reference>
            <spring_stiffness>0</spring_stiffness>
          </dynamics>
        </axis>
      </joint>
      <pose>2.88662 5.79979 0 0 -0 0</pose>
    </model>
    <model name='euro_pallet'>
      <link name='link'>
        <pose>0 0 0 0 -0 0</pose>
        <inertial>
          <mass>20</mass>
          <inertia>
            <ixx>2.43</ixx>
            <ixy>0</ixy>
            <ixz>0</ixz>
            <iyy>1.1</iyy>
            <iyz>0</iyz>
            <izz>3.47</izz>
          </inertia>
          <pose>0 0 0 0 -0 0</pose>
        </inertial>
        <collision name='collision'>
          <pose>0 0 0.05 0 -0 0</pose>
          <geometry>
            <mesh>
              <uri>model://euro_pallet/meshes/pallet.dae</uri>
              <scale>0.1 0.1 0.1</scale>
            </mesh>
          </geometry>
          <max_contacts>10</max_contacts>
          <surface>
            <contact>
              <ode/>
            </contact>
            <bounce/>
            <friction>
              <torsional>
                <ode/>
              </torsional>
              <ode/>
            </friction>
          </surface>
        </collision>
        <visual name='visual'>
          <pose>0 0 0.05 0 -0 0</pose>
          <geometry>
            <mesh>
              <uri>model://euro_pallet/meshes/pallet.dae</uri>
              <scale>0.1 0.1 0.1</scale>
            </mesh>
          </geometry>
        </visual>
        <self_collide>0</self_collide>
        <enable_wind>0</enable_wind>
        <kinematic>0</kinematic>
      </link>
      <pose>0.607245 4.90292 0 0 -0 0</pose>
    </model>
    <model name='gazebo'>
      <static>1</static>
      <link name='link'>
        <collision name='collision'>
          <geometry>
            <mesh>
              <scale>3 3 2.5</scale>
              <uri>model://gazebo/meshes/gazebo.dae</uri>
            </mesh>
          </geometry>
          <max_contacts>10</max_contacts>
          <surface>
            <contact>
              <ode/>
            </contact>
            <bounce/>
            <friction>
              <torsional>
                <ode/>
              </torsional>
              <ode/>
            </friction>
          </surface>
        </collision>
        <visual name='visual'>
          <geometry>
            <mesh>
              <scale>3 3 2.5</scale>
              <uri>model://gazebo/meshes/gazebo.dae</uri>
            </mesh>
          </geometry>
        </visual>
        <self_collide>0</self_collide>
        <enable_wind>0</enable_wind>
        <kinematic>0</kinematic>
      </link>
      <pose>10.1608 -8.0485 0 0 -0 0</pose>
    </model>
    <model name='hatchback_red'>
      <static>1</static>
      <link name='link'>
        <collision name='collision'>
          <pose>0 0 0 0 -0 1.5708</pose>
          <geometry>
            <mesh>
              <scale>0.0254 0.0254 0.0254</scale>
              <uri>model://hatchback_red/meshes/hatchback.obj</uri>
            </mesh>
          </geometry>
          <max_contacts>10</max_contacts>
          <surface>
            <contact>
              <ode/>
            </contact>
            <bounce/>
            <friction>
              <torsional>
                <ode/>
              </torsional>
              <ode/>
            </friction>
          </surface>
        </collision>
        <visual name='visual'>
          <pose>0 0 0 0 -0 1.5708</pose>
          <geometry>
            <mesh>
              <scale>0.0254 0.0254 0.0254</scale>
              <uri>model://hatchback_red/meshes/hatchback.obj</uri>
            </mesh>
          </geometry>
        </visual>
        <self_collide>0</self_collide>
        <enable_wind>0</enable_wind>
        <kinematic>0</kinematic>
      </link>
      <pose>10.457 -1.13637 0 0 -0 0</pose>
    </model>
    <model name='Lamp Post'>
      <static>1</static>
      <link name='link'>
        <collision name='collision'>
          <geometry>
            <mesh>
              <uri>model://lamp_post/meshes/lamp_post.dae</uri>
              <scale>3 3 3</scale>
            </mesh>
          </geometry>
          <max_contacts>10</max_contacts>
          <surface>
            <contact>
              <ode/>
            </contact>
            <bounce/>
            <friction>
              <torsional>
                <ode/>
              </torsional>
              <ode/>
            </friction>
          </surface>
        </collision>
        <visual name='visual'>
          <geometry>
            <mesh>
              <uri>model://lamp_post/meshes/lamp_post.dae</uri>
              <scale>3 3 3</scale>
            </mesh>
          </geometry>
        </visual>
        <self_collide>0</self_collide>
        <enable_wind>0</enable_wind>
        <kinematic>0</kinematic>
      </link>
      <pose>2.16286 8.12859 0 0 -0 0</pose>
    </model>
    <model name='marble_1_5cm'>
      <link name='link'>
        <pose>0 0 0.0075 0 -0 0</pose>
        <inertial>
          <mass>0.0062</mass>
          <inertia>
            <ixx>1.395e-07</ixx>
            <ixy>0</ixy>
            <ixz>0</ixz>
            <iyy>1.395e-07</iyy>
            <iyz>0</iyz>
            <izz>1.395e-07</izz>
          </inertia>
          <pose>0 0 0 0 -0 0</pose>
        </inertial>
        <collision name='collision'>
          <geometry>
            <sphere>
              <radius>0.0075</radius>
            </sphere>
          </geometry>
          <surface>
            <contact>
              <poissons_ratio>0.22</poissons_ratio>
              <elastic_modulus>5.1e+10</elastic_modulus>
              <ode>
                <kp>100000</kp>
                <kd>100</kd>
                <max_vel>100</max_vel>
                <min_depth>0.001</min_depth>
              </ode>
            </contact>
            <friction>
              <torsional>
                <coefficient>1</coefficient>
                <use_patch_radius>0</use_patch_radius>
                <surface_radius>0.01</surface_radius>
                <ode/>
              </torsional>
              <ode/>
            </friction>
            <bounce/>
          </surface>
          <max_contacts>10</max_contacts>
        </collision>
        <visual name='visual'>
          <geometry>
            <sphere>
              <radius>0.0075</radius>
            </sphere>
          </geometry>
          <material>
            <script>
              <uri>file://media/materials/scripts/gazebo.material</uri>
              <name>Gazebo/Blue</name>
            </script>
          </material>
        </visual>
        <velocity_decay>
          <linear>0</linear>
          <angular>0.005</angular>
        </velocity_decay>
        <self_collide>0</self_collide>
        <enable_wind>0</enable_wind>
        <kinematic>0</kinematic>
      </link>
      <pose>1.7705 2.85127 0 0 -0 0</pose>
    </model>
    <model name='mars_rover'>
      <static>1</static>
      <link name='link'>
        <collision name='solar_panel_collision'>
          <pose>0 -0.06945 0.47293 0 -0 0</pose>
          <geometry>
            <box>
              <size>0.87974 0.8821 0.02602</size>
            </box>
          </geometry>
          <max_contacts>10</max_contacts>
          <surface>
            <contact>
              <ode/>
            </contact>
            <bounce/>
            <friction>
              <torsional>
                <ode/>
              </torsional>
              <ode/>
            </friction>
          </surface>
        </collision>
        <collision name='chassis_collision'>
          <pose>0 -0.05 0.31475 0 -0 0</pose>
          <geometry>
            <box>
              <size>0.49522 0.67401 0.28915</size>
            </box>
          </geometry>
          <max_contacts>10</max_contacts>
          <surface>
            <contact>
              <ode/>
            </contact>
            <bounce/>
            <friction>
              <torsional>
                <ode/>
              </torsional>
              <ode/>
            </friction>
          </surface>
        </collision>
        <collision name='rear_left_bumper_collision'>
          <pose>0.30107 0.3835 0.38976 0 -0 0</pose>
          <geometry>
            <box>
              <size>0.04442 0.38897 0.07918</size>
            </box>
          </geometry>
          <max_contacts>10</max_contacts>
          <surface>
            <contact>
              <ode/>
            </contact>
            <bounce/>
            <friction>
              <torsional>
                <ode/>
              </torsional>
              <ode/>
            </friction>
          </surface>
        </collision>
        <collision name='rear_right_bumper_collision'>
          <pose>-0.30107 0.3835 0.38976 0 -0 0</pose>
          <geometry>
            <box>
              <size>0.04442 0.38897 0.07918</size>
            </box>
          </geometry>
          <max_contacts>10</max_contacts>
          <surface>
            <contact>
              <ode/>
            </contact>
            <bounce/>
            <friction>
              <torsional>
                <ode/>
              </torsional>
              <ode/>
            </friction>
          </surface>
        </collision>
        <collision name='rear_bumper_collision'>
          <pose>0 0.59414 0.38976 0 -0 0</pose>
          <geometry>
            <box>
              <size>0.56656 0.04442 0.07918</size>
            </box>
          </geometry>
          <max_contacts>10</max_contacts>
          <surface>
            <contact>
              <ode/>
            </contact>
            <bounce/>
            <friction>
              <torsional>
                <ode/>
              </torsional>
              <ode/>
            </friction>
          </surface>
        </collision>
        <collision name='bin_back_panel_collision'>
          <pose>0 0.47 0.32114 0.69137 -0 0</pose>
          <geometry>
            <box>
              <size>0.43774 0.212366 0.05173</size>
            </box>
          </geometry>
          <max_contacts>10</max_contacts>
          <surface>
            <contact>
              <ode/>
            </contact>
            <bounce/>
            <friction>
              <torsional>
                <ode/>
              </torsional>
              <ode/>
            </friction>
          </surface>
        </collision>
        <collision name='bin_left_panel_collision1'>
          <pose>0.22615 0.32897 0.33193 0 -0 0</pose>
          <geometry>
            <box>
              <size>0.01116 0.19338 0.16304</size>
            </box>
          </geometry>
          <max_contacts>10</max_contacts>
          <surface>
            <contact>
              <ode/>
            </contact>
            <bounce/>
            <friction>
              <torsional>
                <ode/>
              </torsional>
              <ode/>
            </friction>
          </surface>
        </collision>
        <collision name='bin_left_panel_collision2'>
          <pose>0.22615 0.471 0.39308 0 -0 0</pose>
          <geometry>
            <box>
              <size>0.01116 0.15 0.04</size>
            </box>
          </geometry>
          <max_contacts>10</max_contacts>
          <surface>
            <contact>
              <ode/>
            </contact>
            <bounce/>
            <friction>
              <torsional>
                <ode/>
              </torsional>
              <ode/>
            </friction>
          </surface>
        </collision>
        <collision name='bin_left_panel_collision3'>
          <pose>0.22615 0.45 0.35308 0 -0 0</pose>
          <geometry>
            <box>
              <size>0.01116 0.15 0.04</size>
            </box>
          </geometry>
          <max_contacts>10</max_contacts>
          <surface>
            <contact>
              <ode/>
            </contact>
            <bounce/>
            <friction>
              <torsional>
                <ode/>
              </torsional>
              <ode/>
            </friction>
          </surface>
        </collision>
        <collision name='bin_left_panel_collision4'>
          <pose>0.22615 0.39308 0.31308 0 -0 0</pose>
          <geometry>
            <box>
              <size>0.01116 0.15 0.04</size>
            </box>
          </geometry>
          <max_contacts>10</max_contacts>
          <surface>
            <contact>
              <ode/>
            </contact>
            <bounce/>
            <friction>
              <torsional>
                <ode/>
              </torsional>
              <ode/>
            </friction>
          </surface>
        </collision>
        <collision name='bin_right_panel_collision1'>
          <pose>-0.22615 0.32897 0.33193 0 -0 0</pose>
          <geometry>
            <box>
              <size>0.01116 0.19338 0.16304</size>
            </box>
          </geometry>
          <max_contacts>10</max_contacts>
          <surface>
            <contact>
              <ode/>
            </contact>
            <bounce/>
            <friction>
              <torsional>
                <ode/>
              </torsional>
              <ode/>
            </friction>
          </surface>
        </collision>
        <collision name='bin_right_panel_collision2'>
          <pose>-0.22615 0.471 0.39308 0 -0 0</pose>
          <geometry>
            <box>
              <size>0.01116 0.15 0.04</size>
            </box>
          </geometry>
          <max_contacts>10</max_contacts>
          <surface>
            <contact>
              <ode/>
            </contact>
            <bounce/>
            <friction>
              <torsional>
                <ode/>
              </torsional>
              <ode/>
            </friction>
          </surface>
        </collision>
        <collision name='bin_right_panel_collision3'>
          <pose>-0.22615 0.45 0.35308 0 -0 0</pose>
          <geometry>
            <box>
              <size>0.01116 0.15 0.04</size>
            </box>
          </geometry>
          <max_contacts>10</max_contacts>
          <surface>
            <contact>
              <ode/>
            </contact>
            <bounce/>
            <friction>
              <torsional>
                <ode/>
              </torsional>
              <ode/>
            </friction>
          </surface>
        </collision>
        <collision name='bin_right_panel_collision4'>
          <pose>-0.22615 0.39308 0.31308 0 -0 0</pose>
          <geometry>
            <box>
              <size>0.01116 0.15 0.04</size>
            </box>
          </geometry>
          <max_contacts>10</max_contacts>
          <surface>
            <contact>
              <ode/>
            </contact>
            <bounce/>
            <friction>
              <torsional>
                <ode/>
              </torsional>
              <ode/>
            </friction>
          </surface>
        </collision>
        <collision name='bin_front_panel_collision'>
          <pose>0 0.30047 0.32114 2.26207 -0 0</pose>
          <geometry>
            <box>
              <size>0.43774 0.212366 0.05173</size>
            </box>
          </geometry>
          <max_contacts>10</max_contacts>
          <surface>
            <contact>
              <ode/>
            </contact>
            <bounce/>
            <friction>
              <torsional>
                <ode/>
              </torsional>
              <ode/>
            </friction>
          </surface>
        </collision>
        <collision name='front_left_wheel_collision'>
          <pose>0.31103 -0.32115 0.1358 1.5707 0 1.5707</pose>
          <geometry>
            <cylinder>
              <radius>0.1358</radius>
              <length>0.1641</length>
            </cylinder>
          </geometry>
          <max_contacts>10</max_contacts>
          <surface>
            <contact>
              <ode/>
            </contact>
            <bounce/>
            <friction>
              <torsional>
                <ode/>
              </torsional>
              <ode/>
            </friction>
          </surface>
        </collision>
        <collision name='front_right_wheel_collision'>
          <pose>-0.31103 -0.32115 0.1358 1.5707 0 1.5707</pose>
          <geometry>
            <cylinder>
              <radius>0.1358</radius>
              <length>0.1641</length>
            </cylinder>
          </geometry>
          <max_contacts>10</max_contacts>
          <surface>
            <contact>
              <ode/>
            </contact>
            <bounce/>
            <friction>
              <torsional>
                <ode/>
              </torsional>
              <ode/>
            </friction>
          </surface>
        </collision>
        <collision name='rear_left_wheel_collision'>
          <pose>0.31103 0.28049 0.1358 1.5707 0 1.5707</pose>
          <geometry>
            <cylinder>
              <radius>0.1358</radius>
              <length>0.1641</length>
            </cylinder>
          </geometry>
          <max_contacts>10</max_contacts>
          <surface>
            <contact>
              <ode/>
            </contact>
            <bounce/>
            <friction>
              <torsional>
                <ode/>
              </torsional>
              <ode/>
            </friction>
          </surface>
        </collision>
        <collision name='rear_right_wheel_collision'>
          <pose>-0.31103 0.28049 0.1358 1.5707 0 1.5707</pose>
          <geometry>
            <cylinder>
              <radius>0.1358</radius>
              <length>0.1641</length>
            </cylinder>
          </geometry>
          <max_contacts>10</max_contacts>
          <surface>
            <contact>
              <ode/>
            </contact>
            <bounce/>
            <friction>
              <torsional>
                <ode/>
              </torsional>
              <ode/>
            </friction>
          </surface>
        </collision>
        <visual name='visual'>
          <geometry>
            <mesh>
              <uri>model://mars_rover/meshes/rover.dae</uri>
            </mesh>
          </geometry>
        </visual>
        <self_collide>0</self_collide>
        <enable_wind>0</enable_wind>
        <kinematic>0</kinematic>
      </link>
      <pose>4.64474 -8.26488 0 0 -0 0</pose>
    </model>
    <model name='marble_1_5cm_0'>
      <link name='link'>
        <pose>0 0 0.0075 0 -0 0</pose>
        <inertial>
          <mass>0.0062</mass>
          <inertia>
            <ixx>1.395e-07</ixx>
            <ixy>0</ixy>
            <ixz>0</ixz>
            <iyy>1.395e-07</iyy>
            <iyz>0</iyz>
            <izz>1.395e-07</izz>
          </inertia>
          <pose>0 0 0 0 -0 0</pose>
        </inertial>
        <collision name='collision'>
          <geometry>
            <sphere>
              <radius>0.0075</radius>
            </sphere>
          </geometry>
          <surface>
            <contact>
              <poissons_ratio>0.22</poissons_ratio>
              <elastic_modulus>5.1e+10</elastic_modulus>
              <ode>
                <kp>100000</kp>
                <kd>100</kd>
                <max_vel>100</max_vel>
                <min_depth>0.001</min_depth>
              </ode>
            </contact>
            <friction>
              <torsional>
                <coefficient>1</coefficient>
                <use_patch_radius>0</use_patch_radius>
                <surface_radius>0.01</surface_radius>
                <ode/>
              </torsional>
              <ode/>
            </friction>
            <bounce/>
          </surface>
          <max_contacts>10</max_contacts>
        </collision>
        <visual name='visual'>
          <geometry>
            <sphere>
              <radius>0.0075</radius>
            </sphere>
          </geometry>
          <material>
            <script>
              <uri>file://media/materials/scripts/gazebo.material</uri>
              <name>Gazebo/Blue</name>
            </script>
          </material>
        </visual>
        <velocity_decay>
          <linear>0</linear>
          <angular>0.005</angular>
        </velocity_decay>
        <self_collide>0</self_collide>
        <enable_wind>0</enable_wind>
        <kinematic>0</kinematic>
      </link>
      <pose>3.48307 2.14789 0 0 -0 0</pose>
    </model>
    <model name='marble_1_5cm_1'>
      <link name='link'>
        <pose>0 0 0.0075 0 -0 0</pose>
        <inertial>
          <mass>0.0062</mass>
          <inertia>
            <ixx>1.395e-07</ixx>
            <ixy>0</ixy>
            <ixz>0</ixz>
            <iyy>1.395e-07</iyy>
            <iyz>0</iyz>
            <izz>1.395e-07</izz>
          </inertia>
          <pose>0 0 0 0 -0 0</pose>
        </inertial>
        <collision name='collision'>
          <geometry>
            <sphere>
              <radius>0.0075</radius>
            </sphere>
          </geometry>
          <surface>
            <contact>
              <poissons_ratio>0.22</poissons_ratio>
              <elastic_modulus>5.1e+10</elastic_modulus>
              <ode>
                <kp>100000</kp>
                <kd>100</kd>
                <max_vel>100</max_vel>
                <min_depth>0.001</min_depth>
              </ode>
            </contact>
            <friction>
              <torsional>
                <coefficient>1</coefficient>
                <use_patch_radius>0</use_patch_radius>
                <surface_radius>0.01</surface_radius>
                <ode/>
              </torsional>
              <ode/>
            </friction>
            <bounce/>
          </surface>
          <max_contacts>10</max_contacts>
        </collision>
        <visual name='visual'>
          <geometry>
            <sphere>
              <radius>0.0075</radius>
            </sphere>
          </geometry>
          <material>
            <script>
              <uri>file://media/materials/scripts/gazebo.material</uri>
              <name>Gazebo/Blue</name>
            </script>
          </material>
        </visual>
        <velocity_decay>
          <linear>0</linear>
          <angular>0.005</angular>
        </velocity_decay>
        <self_collide>0</self_collide>
        <enable_wind>0</enable_wind>
        <kinematic>0</kinematic>
      </link>
      <pose>2.99077 1.38928 0 0 -0 0</pose>
    </model>
    <model name='oak_tree'>
      <static>1</static>
      <link name='link'>
        <collision name='collision'>
          <geometry>
            <mesh>
              <uri>model://oak_tree/meshes/oak_tree.dae</uri>
            </mesh>
          </geometry>
          <max_contacts>10</max_contacts>
          <surface>
            <contact>
              <ode/>
            </contact>
            <bounce/>
            <friction>
              <torsional>
                <ode/>
              </torsional>
              <ode/>
            </friction>
          </surface>
        </collision>
        <visual name='branch'>
          <geometry>
            <mesh>
              <uri>model://oak_tree/meshes/oak_tree.dae</uri>
              <submesh>
                <name>Branch</name>
              </submesh>
            </mesh>
          </geometry>
          <material>
            <script>
              <uri>model://oak_tree/materials/scripts/</uri>
              <uri>model://oak_tree/materials/textures/</uri>
              <name>OakTree/Branch</name>
            </script>
          </material>
        </visual>
        <visual name='bark'>
          <geometry>
            <mesh>
              <uri>model://oak_tree/meshes/oak_tree.dae</uri>
              <submesh>
                <name>Bark</name>
              </submesh>
            </mesh>
          </geometry>
          <material>
            <script>
              <uri>model://oak_tree/materials/scripts/</uri>
              <uri>model://oak_tree/materials/textures/</uri>
              <name>OakTree/Bark</name>
            </script>
          </material>
        </visual>
        <self_collide>0</self_collide>
        <enable_wind>0</enable_wind>
        <kinematic>0</kinematic>
      </link>
      <pose>5.77899 -12.5457 0 0 -0 0</pose>
    </model>
    <model name='person_standing'>
      <link name='link'>
        <inertial>
          <pose>0 -0.1 0.95 0 -0 0</pose>
          <mass>80</mass>
          <inertia>
            <ixx>24.88</ixx>
            <ixy>0</ixy>
            <ixz>0</ixz>
            <iyy>25.73</iyy>
            <iyz>0</iyz>
            <izz>2.48</izz>
          </inertia>
        </inertial>
        <collision name='bottom'>
          <pose>0 -0.1 0.01 0 -0 0</pose>
          <geometry>
            <box>
              <size>0.5 0.35 0.02</size>
            </box>
          </geometry>
          <max_contacts>10</max_contacts>
          <surface>
            <contact>
              <ode/>
            </contact>
            <bounce/>
            <friction>
              <torsional>
                <ode/>
              </torsional>
              <ode/>
            </friction>
          </surface>
        </collision>
        <collision name='person'>
          <pose>0 0 0.02 0.04 -0 0</pose>
          <geometry>
            <mesh>
              <uri>model://person_standing/meshes/standing.dae</uri>
            </mesh>
          </geometry>
          <max_contacts>10</max_contacts>
          <surface>
            <contact>
              <ode/>
            </contact>
            <bounce/>
            <friction>
              <torsional>
                <ode/>
              </torsional>
              <ode/>
            </friction>
          </surface>
        </collision>
        <visual name='visual'>
          <pose>0 0 0.02 0.04 -0 0</pose>
          <geometry>
            <mesh>
              <uri>model://person_standing/meshes/standing.dae</uri>
            </mesh>
          </geometry>
        </visual>
        <self_collide>0</self_collide>
        <enable_wind>0</enable_wind>
        <kinematic>0</kinematic>
      </link>
      <pose>10.4976 -6.55368 0 0 -0 0</pose>
    </model>
    <model name='wood_cube_10cm'>
      <link name='link'>
        <pose>0 0 0.05 0 -0 0</pose>
        <inertial>
          <mass>0.5167</mass>
          <inertia>
            <ixx>0.000861167</ixx>
            <ixy>0</ixy>
            <ixz>0</ixz>
            <iyy>0.000861167</iyy>
            <iyz>0</iyz>
            <izz>0.000861167</izz>
          </inertia>
          <pose>0 0 0 0 -0 0</pose>
        </inertial>
        <collision name='collision'>
          <geometry>
            <box>
              <size>0.1 0.1 0.1</size>
            </box>
          </geometry>
          <surface>
            <contact>
              <poissons_ratio>0.347</poissons_ratio>
              <elastic_modulus>8.8e+09</elastic_modulus>
              <ode>
                <kp>100000</kp>
                <kd>100</kd>
                <max_vel>100</max_vel>
                <min_depth>0.001</min_depth>
              </ode>
            </contact>
            <friction>
              <torsional>
                <coefficient>1</coefficient>
                <use_patch_radius>0</use_patch_radius>
                <surface_radius>0.01</surface_radius>
                <ode/>
              </torsional>
              <ode/>
            </friction>
            <bounce/>
          </surface>
          <max_contacts>10</max_contacts>
        </collision>
        <visual name='visual'>
          <geometry>
            <box>
              <size>0.1 0.1 0.1</size>
            </box>
          </geometry>
          <material>
            <script>
              <uri>file://media/materials/scripts/gazebo.material</uri>
              <name>Gazebo/Wood</name>
            </script>
          </material>
        </visual>
        <self_collide>0</self_collide>
        <enable_wind>0</enable_wind>
        <kinematic>0</kinematic>
      </link>
      <pose>3.39986 1.53033 0 0 -0 0</pose>
    </model>
    <model name='wood_cube_10cm_0'>
      <link name='link'>
        <pose>0 0 0.05 0 -0 0</pose>
        <inertial>
          <mass>0.5167</mass>
          <inertia>
            <ixx>0.000861167</ixx>
            <ixy>0</ixy>
            <ixz>0</ixz>
            <iyy>0.000861167</iyy>
            <iyz>0</iyz>
            <izz>0.000861167</izz>
          </inertia>
          <pose>0 0 0 0 -0 0</pose>
        </inertial>
        <collision name='collision'>
          <geometry>
            <box>
              <size>0.1 0.1 0.1</size>
            </box>
          </geometry>
          <surface>
            <contact>
              <poissons_ratio>0.347</poissons_ratio>
              <elastic_modulus>8.8e+09</elastic_modulus>
              <ode>
                <kp>100000</kp>
                <kd>100</kd>
                <max_vel>100</max_vel>
                <min_depth>0.001</min_depth>
              </ode>
            </contact>
            <friction>
              <torsional>
                <coefficient>1</coefficient>
                <use_patch_radius>0</use_patch_radius>
                <surface_radius>0.01</surface_radius>
                <ode/>
              </torsional>
              <ode/>
            </friction>
            <bounce/>
          </surface>
          <max_contacts>10</max_contacts>
        </collision>
        <visual name='visual'>
          <geometry>
            <box>
              <size>0.1 0.1 0.1</size>
            </box>
          </geometry>
          <material>
            <script>
              <uri>file://media/materials/scripts/gazebo.material</uri>
              <name>Gazebo/Wood</name>
            </script>
          </material>
        </visual>
        <self_collide>0</self_collide>
        <enable_wind>0</enable_wind>
        <kinematic>0</kinematic>
      </link>
      <pose>3.64038 -0.143743 0 0 -0 0</pose>
    </model>
    <model name='wood_cube_10cm_1'>
      <link name='link'>
        <pose>0 0 0.05 0 -0 0</pose>
        <inertial>
          <mass>0.5167</mass>
          <inertia>
            <ixx>0.000861167</ixx>
            <ixy>0</ixy>
            <ixz>0</ixz>
            <iyy>0.000861167</iyy>
            <iyz>0</iyz>
            <izz>0.000861167</izz>
          </inertia>
          <pose>0 0 0 0 -0 0</pose>
        </inertial>
        <collision name='collision'>
          <geometry>
            <box>
              <size>0.1 0.1 0.1</size>
            </box>
          </geometry>
          <surface>
            <contact>
              <poissons_ratio>0.347</poissons_ratio>
              <elastic_modulus>8.8e+09</elastic_modulus>
              <ode>
                <kp>100000</kp>
                <kd>100</kd>
                <max_vel>100</max_vel>
                <min_depth>0.001</min_depth>
              </ode>
            </contact>
            <friction>
              <torsional>
                <coefficient>1</coefficient>
                <use_patch_radius>0</use_patch_radius>
                <surface_radius>0.01</surface_radius>
                <ode/>
              </torsional>
              <ode/>
            </friction>
            <bounce/>
          </surface>
          <max_contacts>10</max_contacts>
        </collision>
        <visual name='visual'>
          <geometry>
            <box>
              <size>0.1 0.1 0.1</size>
            </box>
          </geometry>
          <material>
            <script>
              <uri>file://media/materials/scripts/gazebo.material</uri>
              <name>Gazebo/Wood</name>
            </script>
          </material>
        </visual>
        <self_collide>0</self_collide>
        <enable_wind>0</enable_wind>
        <kinematic>0</kinematic>
      </link>
      <pose>3.73785 0.576418 0 0 -0 0</pose>
    </model>
    <model name='wood_cube_10cm_2'>
      <link name='link'>
        <pose>0 0 0.05 0 -0 0</pose>
        <inertial>
          <mass>0.5167</mass>
          <inertia>
            <ixx>0.000861167</ixx>
            <ixy>0</ixy>
            <ixz>0</ixz>
            <iyy>0.000861167</iyy>
            <iyz>0</iyz>
            <izz>0.000861167</izz>
          </inertia>
          <pose>0 0 0 0 -0 0</pose>
        </inertial>
        <collision name='collision'>
          <geometry>
            <box>
              <size>0.1 0.1 0.1</size>
            </box>
          </geometry>
          <surface>
            <contact>
              <poissons_ratio>0.347</poissons_ratio>
              <elastic_modulus>8.8e+09</elastic_modulus>
              <ode>
                <kp>100000</kp>
                <kd>100</kd>
                <max_vel>100</max_vel>
                <min_depth>0.001</min_depth>
              </ode>
            </contact>
            <friction>
              <torsional>
                <coefficient>1</coefficient>
                <use_patch_radius>0</use_patch_radius>
                <surface_radius>0.01</surface_radius>
                <ode/>
              </torsional>
              <ode/>
            </friction>
            <bounce/>
          </surface>
          <max_contacts>10</max_contacts>
        </collision>
        <visual name='visual'>
          <geometry>
            <box>
              <size>0.1 0.1 0.1</size>
            </box>
          </geometry>
          <material>
            <script>
              <uri>file://media/materials/scripts/gazebo.material</uri>
              <name>Gazebo/Wood</name>
            </script>
          </material>
        </visual>
        <self_collide>0</self_collide>
        <enable_wind>0</enable_wind>
        <kinematic>0</kinematic>
      </link>
      <pose>3.78858 -0.17009 0 0 -0 0</pose>
    </model>
    <model name='wood_block_10_2_1cm'>
      <link name='link'>
        <pose>0 0 0.005 0 -0 0</pose>
        <inertial>
          <mass>0.0125</mass>
          <inertia>
            <ixx>7.55208e-07</ixx>
            <ixy>0</ixy>
            <ixz>0</ixz>
            <iyy>1.05208e-05</iyy>
            <iyz>0</iyz>
            <izz>1.10677e-05</izz>
          </inertia>
          <pose>0 0 0 0 -0 0</pose>
        </inertial>
        <collision name='collision'>
          <geometry>
            <box>
              <size>0.1 0.025 0.01</size>
            </box>
          </geometry>
          <surface>
            <contact>
              <poissons_ratio>0.347</poissons_ratio>
              <elastic_modulus>8.8e+09</elastic_modulus>
              <ode>
                <kp>100000</kp>
                <kd>1</kd>
                <max_vel>1</max_vel>
                <min_depth>0.001</min_depth>
              </ode>
            </contact>
            <friction>
              <torsional>
                <coefficient>1</coefficient>
                <use_patch_radius>0</use_patch_radius>
                <surface_radius>0.05</surface_radius>
                <ode/>
              </torsional>
              <ode/>
            </friction>
            <bounce/>
          </surface>
          <max_contacts>10</max_contacts>
        </collision>
        <visual name='visual'>
          <geometry>
            <box>
              <size>0.1 0.025 0.01</size>
            </box>
          </geometry>
          <material>
            <script>
              <uri>file://media/materials/scripts/gazebo.material</uri>
              <name>Gazebo/Wood</name>
            </script>
          </material>
        </visual>
        <self_collide>0</self_collide>
        <enable_wind>0</enable_wind>
        <kinematic>0</kinematic>
      </link>
      <pose>3.77407 0.166788 0 0 -0 0</pose>
    </model>
    <model name='wood_block_10_2_1cm_0'>
      <link name='link'>
        <pose>0 0 0.005 0 -0 0</pose>
        <inertial>
          <mass>0.0125</mass>
          <inertia>
            <ixx>7.55208e-07</ixx>
            <ixy>0</ixy>
            <ixz>0</ixz>
            <iyy>1.05208e-05</iyy>
            <iyz>0</iyz>
            <izz>1.10677e-05</izz>
          </inertia>
          <pose>0 0 0 0 -0 0</pose>
        </inertial>
        <collision name='collision'>
          <geometry>
            <box>
              <size>0.1 0.025 0.01</size>
            </box>
          </geometry>
          <surface>
            <contact>
              <poissons_ratio>0.347</poissons_ratio>
              <elastic_modulus>8.8e+09</elastic_modulus>
              <ode>
                <kp>100000</kp>
                <kd>1</kd>
                <max_vel>1</max_vel>
                <min_depth>0.001</min_depth>
              </ode>
            </contact>
            <friction>
              <torsional>
                <coefficient>1</coefficient>
                <use_patch_radius>0</use_patch_radius>
                <surface_radius>0.05</surface_radius>
                <ode/>
              </torsional>
              <ode/>
            </friction>
            <bounce/>
          </surface>
          <max_contacts>10</max_contacts>
        </collision>
        <visual name='visual'>
          <geometry>
            <box>
              <size>0.1 0.025 0.01</size>
            </box>
          </geometry>
          <material>
            <script>
              <uri>file://media/materials/scripts/gazebo.material</uri>
              <name>Gazebo/Wood</name>
            </script>
          </material>
        </visual>
        <self_collide>0</self_collide>
        <enable_wind>0</enable_wind>
        <kinematic>0</kinematic>
      </link>
      <pose>3.93478 0.5192 0 0 -0 0</pose>
    </model>
    <model name='wooden_board'>
      <link name='base'>
        <pose>0 0 0.00523 0 -0 0</pose>
        <inertial>
          <mass>0.2765</mass>
          <inertia>
            <ixx>0.0025148</ixx>
            <ixy>0</ixy>
            <ixz>0</ixz>
            <iyy>0.00024037</iyy>
            <iyz>0</iyz>
            <izz>0.00275013</izz>
          </inertia>
          <pose>0 0 0 0 -0 0</pose>
        </inertial>
        <collision name='collision'>
          <geometry>
            <box>
              <size>0.1016 0.3302 0.01046</size>
            </box>
          </geometry>
          <surface>
            <contact>
              <poissons_ratio>0.347</poissons_ratio>
              <elastic_modulus>8.8e+09</elastic_modulus>
              <ode>
                <kp>100000</kp>
                <kd>100</kd>
                <max_vel>100</max_vel>
                <min_depth>0.001</min_depth>
              </ode>
            </contact>
            <friction>
              <torsional>
                <coefficient>1</coefficient>
                <use_patch_radius>0</use_patch_radius>
                <surface_radius>0.01</surface_radius>
                <ode/>
              </torsional>
              <ode/>
            </friction>
            <bounce/>
          </surface>
          <max_contacts>10</max_contacts>
        </collision>
        <visual name='visual'>
          <geometry>
            <box>
              <size>0.1016 0.3302 0.01046</size>
            </box>
          </geometry>
          <material>
            <script>
              <uri>file://media/materials/scripts/gazebo.material</uri>
              <name>Gazebo/Wood</name>
            </script>
          </material>
        </visual>
        <visual name='tee_nut_1'>
          <pose>0 -0.116 0 0 -0 0</pose>
          <geometry>
            <cylinder>
              <radius>0.00635</radius>
              <length>0.0105646</length>
            </cylinder>
          </geometry>
          <material>
            <script>
              <uri>file://media/materials/scripts/gazebo.material</uri>
              <name>Gazebo/Grey</name>
            </script>
          </material>
        </visual>
        <visual name='tee_nut_2'>
          <pose>0 -0.038 0 0 -0 0</pose>
          <geometry>
            <cylinder>
              <radius>0.00635</radius>
              <length>0.0105646</length>
            </cylinder>
          </geometry>
          <material>
            <script>
              <uri>file://media/materials/scripts/gazebo.material</uri>
              <name>Gazebo/Grey</name>
            </script>
          </material>
        </visual>
        <visual name='tee_nut_3'>
          <pose>0 0.038 0 0 -0 0</pose>
          <geometry>
            <cylinder>
              <radius>0.00635</radius>
              <length>0.0105646</length>
            </cylinder>
          </geometry>
          <material>
            <script>
              <uri>file://media/materials/scripts/gazebo.material</uri>
              <name>Gazebo/Grey</name>
            </script>
          </material>
        </visual>
        <visual name='tee_nut_4'>
          <pose>0 0.116 0 0 -0 0</pose>
          <geometry>
            <cylinder>
              <radius>0.00635</radius>
              <length>0.0105646</length>
            </cylinder>
          </geometry>
          <material>
            <script>
              <uri>file://media/materials/scripts/gazebo.material</uri>
              <name>Gazebo/Grey</name>
            </script>
          </material>
        </visual>
        <self_collide>0</self_collide>
        <enable_wind>0</enable_wind>
        <kinematic>0</kinematic>
      </link>
      <pose>4.64142 1.17578 0 0 -0 0</pose>
    </model>
    <model name='wooden_case'>
      <link name='base'>
        <pose>0 0 0.024 0 -0 0</pose>
        <inertial>
          <pose>-0.022184 0 0.171592 0 -0 0</pose>
          <mass>3.96264</mass>
          <inertia>
            <ixx>0.213536</ixx>
            <ixy>0</ixy>
            <ixz>0.000779377</ixz>
            <iyy>0.0708943</iyy>
            <iyz>0</iyz>
            <izz>0.154604</izz>
          </inertia>
        </inertial>
        <collision name='collision_back'>
          <pose>-0.053975 0 0.1778 0 -0 0</pose>
          <geometry>
            <box>
              <size>0.01905 0.5461 0.3175</size>
            </box>
          </geometry>
          <surface>
            <contact>
              <poissons_ratio>0.347</poissons_ratio>
              <elastic_modulus>8.8e+09</elastic_modulus>
              <ode>
                <kp>100000</kp>
                <kd>100</kd>
                <max_vel>100</max_vel>
                <min_depth>0.001</min_depth>
              </ode>
            </contact>
            <friction>
              <torsional>
                <coefficient>1</coefficient>
                <use_patch_radius>0</use_patch_radius>
                <surface_radius>0.01</surface_radius>
                <ode/>
              </torsional>
              <ode/>
            </friction>
            <bounce/>
          </surface>
          <max_contacts>10</max_contacts>
        </collision>
        <visual name='visual_back'>
          <pose>-0.053975 0 0.1778 0 -0 0</pose>
          <geometry>
            <box>
              <size>0.01905 0.5461 0.3175</size>
            </box>
          </geometry>
          <material>
            <script>
              <uri>file://media/materials/scripts/gazebo.material</uri>
              <name>Gazebo/Wood</name>
            </script>
          </material>
        </visual>
        <collision name='collision_bottom'>
          <pose>0 0 0.009525 0 -0 0</pose>
          <geometry>
            <box>
              <size>0.127 0.5842 0.01905</size>
            </box>
          </geometry>
          <surface>
            <contact>
              <poissons_ratio>0.347</poissons_ratio>
              <elastic_modulus>8.8e+09</elastic_modulus>
              <ode>
                <kp>100000</kp>
                <kd>100</kd>
                <max_vel>100</max_vel>
                <min_depth>0.001</min_depth>
              </ode>
            </contact>
            <friction>
              <torsional>
                <coefficient>1</coefficient>
                <use_patch_radius>0</use_patch_radius>
                <surface_radius>0.01</surface_radius>
                <ode/>
              </torsional>
              <ode/>
            </friction>
            <bounce/>
          </surface>
          <max_contacts>10</max_contacts>
        </collision>
        <visual name='visual_bottom'>
          <pose>0 0 0.009525 0 -0 0</pose>
          <geometry>
            <box>
              <size>0.127 0.5842 0.01905</size>
            </box>
          </geometry>
          <material>
            <script>
              <uri>file://media/materials/scripts/gazebo.material</uri>
              <name>Gazebo/Wood</name>
            </script>
          </material>
        </visual>
        <collision name='collision_top'>
          <pose>0 0 0.346075 0 -0 0</pose>
          <geometry>
            <box>
              <size>0.127 0.5842 0.01905</size>
            </box>
          </geometry>
          <surface>
            <contact>
              <poissons_ratio>0.347</poissons_ratio>
              <elastic_modulus>8.8e+09</elastic_modulus>
              <ode>
                <kp>100000</kp>
                <kd>100</kd>
                <max_vel>100</max_vel>
                <min_depth>0.001</min_depth>
              </ode>
            </contact>
            <friction>
              <torsional>
                <coefficient>1</coefficient>
                <use_patch_radius>0</use_patch_radius>
                <surface_radius>0.01</surface_radius>
                <ode/>
              </torsional>
              <ode/>
            </friction>
            <bounce/>
          </surface>
          <max_contacts>10</max_contacts>
        </collision>
        <visual name='visual_top'>
          <pose>0 0 0.346075 0 -0 0</pose>
          <geometry>
            <box>
              <size>0.127 0.5842 0.01905</size>
            </box>
          </geometry>
          <material>
            <script>
              <uri>file://media/materials/scripts/gazebo.material</uri>
              <name>Gazebo/Wood</name>
            </script>
          </material>
        </visual>
        <collision name='collision_left'>
          <pose>0 -0.282575 0.1778 0 -0 0</pose>
          <geometry>
            <box>
              <size>0.127 0.01905 0.3175</size>
            </box>
          </geometry>
          <surface>
            <contact>
              <poissons_ratio>0.347</poissons_ratio>
              <elastic_modulus>8.8e+09</elastic_modulus>
              <ode>
                <kp>100000</kp>
                <kd>100</kd>
                <max_vel>100</max_vel>
                <min_depth>0.001</min_depth>
              </ode>
            </contact>
            <friction>
              <torsional>
                <coefficient>1</coefficient>
                <use_patch_radius>0</use_patch_radius>
                <surface_radius>0.01</surface_radius>
                <ode/>
              </torsional>
              <ode/>
            </friction>
            <bounce/>
          </surface>
          <max_contacts>10</max_contacts>
        </collision>
        <visual name='visual_left'>
          <pose>0 -0.282575 0.1778 0 -0 0</pose>
          <geometry>
            <box>
              <size>0.127 0.01905 0.3175</size>
            </box>
          </geometry>
          <material>
            <script>
              <uri>file://media/materials/scripts/gazebo.material</uri>
              <name>Gazebo/Wood</name>
            </script>
          </material>
        </visual>
        <collision name='collision_right'>
          <pose>0 0.282575 0.1778 0 -0 0</pose>
          <geometry>
            <box>
              <size>0.127 0.01905 0.3175</size>
            </box>
          </geometry>
          <surface>
            <contact>
              <poissons_ratio>0.347</poissons_ratio>
              <elastic_modulus>8.8e+09</elastic_modulus>
              <ode>
                <kp>100000</kp>
                <kd>100</kd>
                <max_vel>100</max_vel>
                <min_depth>0.001</min_depth>
              </ode>
            </contact>
            <friction>
              <torsional>
                <coefficient>1</coefficient>
                <use_patch_radius>0</use_patch_radius>
                <surface_radius>0.01</surface_radius>
                <ode/>
              </torsional>
              <ode/>
            </friction>
            <bounce/>
          </surface>
          <max_contacts>10</max_contacts>
        </collision>
        <visual name='visual_right'>
          <pose>0 0.282575 0.1778 0 -0 0</pose>
          <geometry>
            <box>
              <size>0.127 0.01905 0.3175</size>
            </box>
          </geometry>
          <material>
            <script>
              <uri>file://media/materials/scripts/gazebo.material</uri>
              <name>Gazebo/Wood</name>
            </script>
          </material>
        </visual>
        <collision name='collision_block_left'>
          <pose>0.0095 -0.2151 -0.012 0 -0 0</pose>
          <geometry>
            <box>
              <size>0.108 0.05 0.024</size>
            </box>
          </geometry>
          <surface>
            <contact>
              <poissons_ratio>0.347</poissons_ratio>
              <elastic_modulus>8.8e+09</elastic_modulus>
              <ode>
                <kp>100000</kp>
                <kd>100</kd>
                <max_vel>100</max_vel>
                <min_depth>0.001</min_depth>
              </ode>
            </contact>
            <friction>
              <torsional>
                <coefficient>1</coefficient>
                <use_patch_radius>0</use_patch_radius>
                <surface_radius>0.01</surface_radius>
                <ode/>
              </torsional>
              <ode/>
            </friction>
            <bounce/>
          </surface>
          <max_contacts>10</max_contacts>
        </collision>
        <visual name='visual_block_left'>
          <pose>0.0095 -0.2151 -0.012 0 -0 0</pose>
          <geometry>
            <box>
              <size>0.108 0.05 0.024</size>
            </box>
          </geometry>
          <material>
            <script>
              <uri>file://media/materials/scripts/gazebo.material</uri>
              <name>Gazebo/Wood</name>
            </script>
          </material>
        </visual>
        <collision name='collision_block_right'>
          <pose>0.0095 0.2151 -0.012 0 -0 0</pose>
          <geometry>
            <box>
              <size>0.108 0.05 0.024</size>
            </box>
          </geometry>
          <surface>
            <contact>
              <poissons_ratio>0.347</poissons_ratio>
              <elastic_modulus>8.8e+09</elastic_modulus>
              <ode>
                <kp>100000</kp>
                <kd>100</kd>
                <max_vel>100</max_vel>
                <min_depth>0.001</min_depth>
              </ode>
            </contact>
            <friction>
              <torsional>
                <coefficient>1</coefficient>
                <use_patch_radius>0</use_patch_radius>
                <surface_radius>0.01</surface_radius>
                <ode/>
              </torsional>
              <ode/>
            </friction>
            <bounce/>
          </surface>
          <max_contacts>10</max_contacts>
        </collision>
        <visual name='visual_block_right'>
          <pose>0.0095 0.2151 -0.012 0 -0 0</pose>
          <geometry>
            <box>
              <size>0.108 0.05 0.024</size>
            </box>
          </geometry>
          <material>
            <script>
              <uri>file://media/materials/scripts/gazebo.material</uri>
              <name>Gazebo/Wood</name>
            </script>
          </material>
        </visual>
        <self_collide>0</self_collide>
        <enable_wind>0</enable_wind>
        <kinematic>0</kinematic>
      </link>
      <link name='lid'>
        <pose>0.243775 0 0.009525 0 -0 0</pose>
        <inertial>
          <mass>1.97874</mass>
          <inertia>
            <ixx>0.0563367</ixx>
            <ixy>0</ixy>
            <ixz>0</ixz>
            <iyy>0.020911</iyy>
            <iyz>0</iyz>
            <izz>0.0771281</izz>
          </inertia>
          <pose>0 0 0 0 -0 0</pose>
        </inertial>
        <collision name='collision'>
          <geometry>
            <box>
              <size>0.3556 0.5842 0.01905</size>
            </box>
          </geometry>
          <surface>
            <contact>
              <poissons_ratio>0.347</poissons_ratio>
              <elastic_modulus>8.8e+09</elastic_modulus>
              <ode>
                <kp>100000</kp>
                <kd>100</kd>
                <max_vel>100</max_vel>
                <min_depth>0.001</min_depth>
              </ode>
            </contact>
            <friction>
              <torsional>
                <coefficient>1</coefficient>
                <use_patch_radius>0</use_patch_radius>
                <surface_radius>0.01</surface_radius>
                <ode/>
              </torsional>
              <ode/>
            </friction>
            <bounce/>
          </surface>
          <max_contacts>10</max_contacts>
        </collision>
        <visual name='visual'>
          <geometry>
            <box>
              <size>0.3556 0.5842 0.01905</size>
            </box>
          </geometry>
          <material>
            <script>
              <uri>file://media/materials/scripts/gazebo.material</uri>
              <name>Gazebo/Wood</name>
            </script>
          </material>
        </visual>
        <visual name='tee_nut_1'>
          <pose>0.122 -0.216 0 0 -0 0</pose>
          <geometry>
            <cylinder>
              <radius>0.00635</radius>
              <length>0.0192405</length>
            </cylinder>
          </geometry>
          <material>
            <script>
              <uri>file://media/materials/scripts/gazebo.material</uri>
              <name>Gazebo/Grey</name>
            </script>
          </material>
        </visual>
        <visual name='tee_nut_2'>
          <pose>0.122 -0.088 0 0 -0 0</pose>
          <geometry>
            <cylinder>
              <radius>0.00635</radius>
              <length>0.0192405</length>
            </cylinder>
          </geometry>
          <material>
            <script>
              <uri>file://media/materials/scripts/gazebo.material</uri>
              <name>Gazebo/Grey</name>
            </script>
          </material>
        </visual>
        <visual name='tee_nut_3'>
          <pose>0.122 0.088 0 0 -0 0</pose>
          <geometry>
            <cylinder>
              <radius>0.00635</radius>
              <length>0.0192405</length>
            </cylinder>
          </geometry>
          <material>
            <script>
              <uri>file://media/materials/scripts/gazebo.material</uri>
              <name>Gazebo/Grey</name>
            </script>
          </material>
        </visual>
        <visual name='tee_nut_4'>
          <pose>0.122 0.216 0 0 -0 0</pose>
          <geometry>
            <cylinder>
              <radius>0.00635</radius>
              <length>0.0192405</length>
            </cylinder>
          </geometry>
          <material>
            <script>
              <uri>file://media/materials/scripts/gazebo.material</uri>
              <name>Gazebo/Grey</name>
            </script>
          </material>
        </visual>
        <self_collide>0</self_collide>
        <enable_wind>0</enable_wind>
        <kinematic>0</kinematic>
      </link>
      <joint name='lid_hinge' type='revolute'>
        <pose>-0.1778 0 0.01905 0 -0 0</pose>
        <parent>base</parent>
        <child>lid</child>
        <axis>
          <xyz>0 1 0</xyz>
          <limit>
            <upper>0.523599</upper>
            <lower>-1.5708</lower>
          </limit>
          <dynamics>
            <spring_reference>0</spring_reference>
            <spring_stiffness>0</spring_stiffness>
          </dynamics>
        </axis>
      </joint>
      <pose>3.84802 0.905992 0 0 -0 0</pose>
    </model>
    <model name='wooden_case_metal_peg'>
      <frame name='wooden_case::__model__' attached_to='wooden_case::base'>
        <pose relative_to='__model__'>0 0 0 0 -0 0</pose>
      </frame>
      <link name='wooden_case::base'>
        <pose relative_to='wooden_case::__model__'>0 0 0.024 0 -0 0</pose>
        <inertial>
          <pose>-0.022184 0 0.171592 0 -0 0</pose>
          <mass>3.96264</mass>
          <inertia>
            <ixx>0.213536</ixx>
            <ixy>0</ixy>
            <ixz>0.000779377</ixz>
            <iyy>0.0708943</iyy>
            <iyz>0</iyz>
            <izz>0.154604</izz>
          </inertia>
        </inertial>
        <collision name='collision_back'>
          <pose>-0.053975 0 0.1778 0 -0 0</pose>
          <geometry>
            <box>
              <size>0.01905 0.5461 0.3175</size>
            </box>
          </geometry>
          <surface>
            <contact>
              <poissons_ratio>0.347</poissons_ratio>
              <elastic_modulus>8.8e+09</elastic_modulus>
              <ode>
                <kp>100000</kp>
                <kd>100</kd>
                <max_vel>100</max_vel>
                <min_depth>0.001</min_depth>
              </ode>
            </contact>
            <friction>
              <torsional>
                <coefficient>1</coefficient>
                <use_patch_radius>0</use_patch_radius>
                <surface_radius>0.01</surface_radius>
                <ode/>
              </torsional>
              <ode/>
            </friction>
            <bounce/>
          </surface>
          <max_contacts>10</max_contacts>
        </collision>
        <visual name='visual_back'>
          <pose>-0.053975 0 0.1778 0 -0 0</pose>
          <geometry>
            <box>
              <size>0.01905 0.5461 0.3175</size>
            </box>
          </geometry>
          <material>
            <script>
              <uri>file://media/materials/scripts/gazebo.material</uri>
              <name>Gazebo/Wood</name>
            </script>
          </material>
        </visual>
        <collision name='collision_bottom'>
          <pose>0 0 0.009525 0 -0 0</pose>
          <geometry>
            <box>
              <size>0.127 0.5842 0.01905</size>
            </box>
          </geometry>
          <surface>
            <contact>
              <poissons_ratio>0.347</poissons_ratio>
              <elastic_modulus>8.8e+09</elastic_modulus>
              <ode>
                <kp>100000</kp>
                <kd>100</kd>
                <max_vel>100</max_vel>
                <min_depth>0.001</min_depth>
              </ode>
            </contact>
            <friction>
              <torsional>
                <coefficient>1</coefficient>
                <use_patch_radius>0</use_patch_radius>
                <surface_radius>0.01</surface_radius>
                <ode/>
              </torsional>
              <ode/>
            </friction>
            <bounce/>
          </surface>
          <max_contacts>10</max_contacts>
        </collision>
        <visual name='visual_bottom'>
          <pose>0 0 0.009525 0 -0 0</pose>
          <geometry>
            <box>
              <size>0.127 0.5842 0.01905</size>
            </box>
          </geometry>
          <material>
            <script>
              <uri>file://media/materials/scripts/gazebo.material</uri>
              <name>Gazebo/Wood</name>
            </script>
          </material>
        </visual>
        <collision name='collision_top'>
          <pose>0 0 0.346075 0 -0 0</pose>
          <geometry>
            <box>
              <size>0.127 0.5842 0.01905</size>
            </box>
          </geometry>
          <surface>
            <contact>
              <poissons_ratio>0.347</poissons_ratio>
              <elastic_modulus>8.8e+09</elastic_modulus>
              <ode>
                <kp>100000</kp>
                <kd>100</kd>
                <max_vel>100</max_vel>
                <min_depth>0.001</min_depth>
              </ode>
            </contact>
            <friction>
              <torsional>
                <coefficient>1</coefficient>
                <use_patch_radius>0</use_patch_radius>
                <surface_radius>0.01</surface_radius>
                <ode/>
              </torsional>
              <ode/>
            </friction>
            <bounce/>
          </surface>
          <max_contacts>10</max_contacts>
        </collision>
        <visual name='visual_top'>
          <pose>0 0 0.346075 0 -0 0</pose>
          <geometry>
            <box>
              <size>0.127 0.5842 0.01905</size>
            </box>
          </geometry>
          <material>
            <script>
              <uri>file://media/materials/scripts/gazebo.material</uri>
              <name>Gazebo/Wood</name>
            </script>
          </material>
        </visual>
        <collision name='collision_left'>
          <pose>0 -0.282575 0.1778 0 -0 0</pose>
          <geometry>
            <box>
              <size>0.127 0.01905 0.3175</size>
            </box>
          </geometry>
          <surface>
            <contact>
              <poissons_ratio>0.347</poissons_ratio>
              <elastic_modulus>8.8e+09</elastic_modulus>
              <ode>
                <kp>100000</kp>
                <kd>100</kd>
                <max_vel>100</max_vel>
                <min_depth>0.001</min_depth>
              </ode>
            </contact>
            <friction>
              <torsional>
                <coefficient>1</coefficient>
                <use_patch_radius>0</use_patch_radius>
                <surface_radius>0.01</surface_radius>
                <ode/>
              </torsional>
              <ode/>
            </friction>
            <bounce/>
          </surface>
          <max_contacts>10</max_contacts>
        </collision>
        <visual name='visual_left'>
          <pose>0 -0.282575 0.1778 0 -0 0</pose>
          <geometry>
            <box>
              <size>0.127 0.01905 0.3175</size>
            </box>
          </geometry>
          <material>
            <script>
              <uri>file://media/materials/scripts/gazebo.material</uri>
              <name>Gazebo/Wood</name>
            </script>
          </material>
        </visual>
        <collision name='collision_right'>
          <pose>0 0.282575 0.1778 0 -0 0</pose>
          <geometry>
            <box>
              <size>0.127 0.01905 0.3175</size>
            </box>
          </geometry>
          <surface>
            <contact>
              <poissons_ratio>0.347</poissons_ratio>
              <elastic_modulus>8.8e+09</elastic_modulus>
              <ode>
                <kp>100000</kp>
                <kd>100</kd>
                <max_vel>100</max_vel>
                <min_depth>0.001</min_depth>
              </ode>
            </contact>
            <friction>
              <torsional>
                <coefficient>1</coefficient>
                <use_patch_radius>0</use_patch_radius>
                <surface_radius>0.01</surface_radius>
                <ode/>
              </torsional>
              <ode/>
            </friction>
            <bounce/>
          </surface>
          <max_contacts>10</max_contacts>
        </collision>
        <visual name='visual_right'>
          <pose>0 0.282575 0.1778 0 -0 0</pose>
          <geometry>
            <box>
              <size>0.127 0.01905 0.3175</size>
            </box>
          </geometry>
          <material>
            <script>
              <uri>file://media/materials/scripts/gazebo.material</uri>
              <name>Gazebo/Wood</name>
            </script>
          </material>
        </visual>
        <collision name='collision_block_left'>
          <pose>0.0095 -0.2151 -0.012 0 -0 0</pose>
          <geometry>
            <box>
              <size>0.108 0.05 0.024</size>
            </box>
          </geometry>
          <surface>
            <contact>
              <poissons_ratio>0.347</poissons_ratio>
              <elastic_modulus>8.8e+09</elastic_modulus>
              <ode>
                <kp>100000</kp>
                <kd>100</kd>
                <max_vel>100</max_vel>
                <min_depth>0.001</min_depth>
              </ode>
            </contact>
            <friction>
              <torsional>
                <coefficient>1</coefficient>
                <use_patch_radius>0</use_patch_radius>
                <surface_radius>0.01</surface_radius>
                <ode/>
              </torsional>
              <ode/>
            </friction>
            <bounce/>
          </surface>
          <max_contacts>10</max_contacts>
        </collision>
        <visual name='visual_block_left'>
          <pose>0.0095 -0.2151 -0.012 0 -0 0</pose>
          <geometry>
            <box>
              <size>0.108 0.05 0.024</size>
            </box>
          </geometry>
          <material>
            <script>
              <uri>file://media/materials/scripts/gazebo.material</uri>
              <name>Gazebo/Wood</name>
            </script>
          </material>
        </visual>
        <collision name='collision_block_right'>
          <pose>0.0095 0.2151 -0.012 0 -0 0</pose>
          <geometry>
            <box>
              <size>0.108 0.05 0.024</size>
            </box>
          </geometry>
          <surface>
            <contact>
              <poissons_ratio>0.347</poissons_ratio>
              <elastic_modulus>8.8e+09</elastic_modulus>
              <ode>
                <kp>100000</kp>
                <kd>100</kd>
                <max_vel>100</max_vel>
                <min_depth>0.001</min_depth>
              </ode>
            </contact>
            <friction>
              <torsional>
                <coefficient>1</coefficient>
                <use_patch_radius>0</use_patch_radius>
                <surface_radius>0.01</surface_radius>
                <ode/>
              </torsional>
              <ode/>
            </friction>
            <bounce/>
          </surface>
          <max_contacts>10</max_contacts>
        </collision>
        <visual name='visual_block_right'>
          <pose>0.0095 0.2151 -0.012 0 -0 0</pose>
          <geometry>
            <box>
              <size>0.108 0.05 0.024</size>
            </box>
          </geometry>
          <material>
            <script>
              <uri>file://media/materials/scripts/gazebo.material</uri>
              <name>Gazebo/Wood</name>
            </script>
          </material>
        </visual>
        <self_collide>0</self_collide>
        <enable_wind>0</enable_wind>
        <kinematic>0</kinematic>
      </link>
      <link name='wooden_case::lid'>
        <pose relative_to='wooden_case::__model__'>0.243775 0 0.009525 0 -0 0</pose>
        <inertial>
          <mass>1.97874</mass>
          <inertia>
            <ixx>0.0563367</ixx>
            <ixy>0</ixy>
            <ixz>0</ixz>
            <iyy>0.020911</iyy>
            <iyz>0</iyz>
            <izz>0.0771281</izz>
          </inertia>
          <pose>0 0 0 0 -0 0</pose>
        </inertial>
        <collision name='collision'>
          <geometry>
            <box>
              <size>0.3556 0.5842 0.01905</size>
            </box>
          </geometry>
          <surface>
            <contact>
              <poissons_ratio>0.347</poissons_ratio>
              <elastic_modulus>8.8e+09</elastic_modulus>
              <ode>
                <kp>100000</kp>
                <kd>100</kd>
                <max_vel>100</max_vel>
                <min_depth>0.001</min_depth>
              </ode>
            </contact>
            <friction>
              <torsional>
                <coefficient>1</coefficient>
                <use_patch_radius>0</use_patch_radius>
                <surface_radius>0.01</surface_radius>
                <ode/>
              </torsional>
              <ode/>
            </friction>
            <bounce/>
          </surface>
          <max_contacts>10</max_contacts>
        </collision>
        <visual name='visual'>
          <geometry>
            <box>
              <size>0.3556 0.5842 0.01905</size>
            </box>
          </geometry>
          <material>
            <script>
              <uri>file://media/materials/scripts/gazebo.material</uri>
              <name>Gazebo/Wood</name>
            </script>
          </material>
        </visual>
        <visual name='tee_nut_1'>
          <pose>0.122 -0.216 0 0 -0 0</pose>
          <geometry>
            <cylinder>
              <radius>0.00635</radius>
              <length>0.0192405</length>
            </cylinder>
          </geometry>
          <material>
            <script>
              <uri>file://media/materials/scripts/gazebo.material</uri>
              <name>Gazebo/Grey</name>
            </script>
          </material>
        </visual>
        <visual name='tee_nut_2'>
          <pose>0.122 -0.088 0 0 -0 0</pose>
          <geometry>
            <cylinder>
              <radius>0.00635</radius>
              <length>0.0192405</length>
            </cylinder>
          </geometry>
          <material>
            <script>
              <uri>file://media/materials/scripts/gazebo.material</uri>
              <name>Gazebo/Grey</name>
            </script>
          </material>
        </visual>
        <visual name='tee_nut_3'>
          <pose>0.122 0.088 0 0 -0 0</pose>
          <geometry>
            <cylinder>
              <radius>0.00635</radius>
              <length>0.0192405</length>
            </cylinder>
          </geometry>
          <material>
            <script>
              <uri>file://media/materials/scripts/gazebo.material</uri>
              <name>Gazebo/Grey</name>
            </script>
          </material>
        </visual>
        <visual name='tee_nut_4'>
          <pose>0.122 0.216 0 0 -0 0</pose>
          <geometry>
            <cylinder>
              <radius>0.00635</radius>
              <length>0.0192405</length>
            </cylinder>
          </geometry>
          <material>
            <script>
              <uri>file://media/materials/scripts/gazebo.material</uri>
              <name>Gazebo/Grey</name>
            </script>
          </material>
        </visual>
        <self_collide>0</self_collide>
        <enable_wind>0</enable_wind>
        <kinematic>0</kinematic>
      </link>
      <joint name='wooden_case::lid_hinge' type='revolute'>
        <pose>-0.1778 0 0.01905 0 -0 0</pose>
        <parent>wooden_case::base</parent>
        <child>wooden_case::lid</child>
        <axis>
          <xyz>0 1 0</xyz>
          <limit>
            <upper>0.523599</upper>
            <lower>-1.5708</lower>
          </limit>
          <dynamics>
            <spring_reference>0</spring_reference>
            <spring_stiffness>0</spring_stiffness>
          </dynamics>
        </axis>
      </joint>
      <frame name='peg::__model__' attached_to='peg::link'>
        <pose relative_to='__model__'>0.365774 0.216 0.01905 0 -0 0</pose>
      </frame>
      <link name='peg::link'>
        <pose relative_to='peg::__model__'>0 0 0.031 0 -0 0</pose>
        <inertial>
          <mass>0.0121</mass>
          <inertia>
            <ixx>3.90898e-06</ixx>
            <ixy>0</ixy>
            <ixz>0</ixz>
            <iyy>3.90898e-06</iyy>
            <iyz>0</iyz>
            <izz>6.58845e-08</izz>
          </inertia>
          <pose>0 0 0 0 -0 0</pose>
        </inertial>
        <collision name='collision'>
          <geometry>
            <cylinder>
              <radius>0.0033</radius>
              <length>0.062</length>
            </cylinder>
          </geometry>
          <surface>
            <contact>
              <poissons_ratio>0.305</poissons_ratio>
              <elastic_modulus>2e+11</elastic_modulus>
              <ode>
                <kp>100000</kp>
                <kd>100</kd>
                <max_vel>100</max_vel>
                <min_depth>0.001</min_depth>
              </ode>
            </contact>
            <friction>
              <torsional>
                <coefficient>1</coefficient>
                <use_patch_radius>0</use_patch_radius>
                <surface_radius>0.01</surface_radius>
                <ode/>
              </torsional>
              <ode/>
            </friction>
            <bounce/>
          </surface>
          <max_contacts>10</max_contacts>
        </collision>
        <visual name='visual'>
          <geometry>
            <cylinder>
              <radius>0.0033</radius>
              <length>0.062</length>
            </cylinder>
          </geometry>
          <material>
            <script>
              <uri>file://media/materials/scripts/gazebo.material</uri>
              <name>Gazebo/Grey</name>
            </script>
          </material>
        </visual>
        <self_collide>0</self_collide>
        <enable_wind>0</enable_wind>
        <kinematic>0</kinematic>
      </link>
      <joint name='case_peg' type='revolute'>
        <child>peg::link</child>
        <parent>wooden_case::lid</parent>
        <axis>
          <xyz>0 0 1</xyz>
          <limit>
            <upper>0</upper>
            <lower>0</lower>
          </limit>
          <dynamics>
            <spring_reference>0</spring_reference>
            <spring_stiffness>0</spring_stiffness>
          </dynamics>
        </axis>
      </joint>
      <pose>3.57623 0.150512 0 0 -0 0</pose>
    </model>
    <model name='car_wheel'>
      <link name='link'>
        <pose>0 0 0.21682 0 1.5707 0</pose>
        <inertial>
          <mass>12</mass>
          <inertia>
            <ixx>0.167005</ixx>
            <ixy>0</ixy>
            <ixz>0</ixz>
            <iyy>0.167005</iyy>
            <iyz>0</iyz>
            <izz>0.282065</izz>
          </inertia>
          <pose>0 0 0 0 -0 0</pose>
        </inertial>
        <collision name='collision'>
          <geometry>
            <cylinder>
              <radius>0.21682</radius>
              <length>0.16116</length>
            </cylinder>
          </geometry>
          <surface>
            <friction>
              <ode>
                <mu>1</mu>
                <mu2>1</mu2>
                <fdir1>0 0 1</fdir1>
                <slip1>0</slip1>
                <slip2>0</slip2>
              </ode>
              <torsional>
                <ode/>
              </torsional>
            </friction>
            <contact>
              <ode>
                <min_depth>0.005</min_depth>
                <kp>1e+08</kp>
              </ode>
            </contact>
            <bounce/>
          </surface>
          <max_contacts>10</max_contacts>
        </collision>
        <visual name='visual'>
          <pose>0 0 -0.08058 0 -0 0</pose>
          <geometry>
            <mesh>
              <uri>model://car_wheel/meshes/car_wheel.dae</uri>
            </mesh>
          </geometry>
        </visual>
        <self_collide>0</self_collide>
        <enable_wind>0</enable_wind>
        <kinematic>0</kinematic>
      </link>
      <pose>3.71293 3.67668 0 0 -0 0</pose>
    </model>
    <model name='cessna_c172'>
      <pose>-2.55732 -11.8023 0.495 0 -0 0</pose>
      <link name='body'>
        <inertial>
          <mass>680.389</mass>
          <inertia>
            <ixx>1285.32</ixx>
            <ixy>0</ixy>
            <iyy>1824.93</iyy>
            <ixz>0</ixz>
            <iyz>0</iyz>
            <izz>2666.89</izz>
          </inertia>
          <pose>-0.0414 0 0.9271 0 -0 0</pose>
        </inertial>
        <collision name='collision'>
          <geometry>
            <mesh>
              <uri>model://cessna/meshes/body.dae</uri>
            </mesh>
          </geometry>
          <max_contacts>10</max_contacts>
          <surface>
            <contact>
              <ode/>
            </contact>
            <bounce/>
            <friction>
              <torsional>
                <ode/>
              </torsional>
              <ode/>
            </friction>
          </surface>
        </collision>
        <visual name='visual'>
          <geometry>
            <mesh>
              <uri>model://cessna/meshes/body.dae</uri>
            </mesh>
          </geometry>
        </visual>
        <self_collide>0</self_collide>
        <enable_wind>0</enable_wind>
        <kinematic>0</kinematic>
      </link>
      <link name='left_aileron'>
        <inertial>
          <mass>2</mass>
          <inertia>
            <ixx>0.8434</ixx>
            <ixy>0</ixy>
            <iyy>0.0119</iyy>
            <ixz>0</ixz>
            <iyz>0</iyz>
            <izz>0.855</izz>
          </inertia>
          <pose>-1.65 3.7 1.5 0.05 -0 -0.12</pose>
        </inertial>
        <collision name='collision'>
          <geometry>
            <mesh>
              <uri>model://cessna/meshes/left_aileron.dae</uri>
            </mesh>
          </geometry>
          <max_contacts>10</max_contacts>
          <surface>
            <contact>
              <ode/>
            </contact>
            <bounce/>
            <friction>
              <torsional>
                <ode/>
              </torsional>
              <ode/>
            </friction>
          </surface>
        </collision>
        <visual name='visual'>
          <geometry>
            <mesh>
              <uri>model://cessna/meshes/left_aileron.dae</uri>
            </mesh>
          </geometry>
        </visual>
        <self_collide>0</self_collide>
        <enable_wind>0</enable_wind>
        <kinematic>0</kinematic>
      </link>
      <link name='left_flap'>
        <inertial>
          <mass>2</mass>
          <inertia>
            <ixx>0.6747</ixx>
            <ixy>0</ixy>
            <iyy>0.0242</iyy>
            <ixz>0</ixz>
            <iyz>0</iyz>
            <izz>0.6962</izz>
          </inertia>
          <pose>-1.8 1.55 1.43 0.02 -0 0</pose>
        </inertial>
        <collision name='collision'>
          <geometry>
            <mesh>
              <uri>model://cessna/meshes/left_flap.dae</uri>
            </mesh>
          </geometry>
          <max_contacts>10</max_contacts>
          <surface>
            <contact>
              <ode/>
            </contact>
            <bounce/>
            <friction>
              <torsional>
                <ode/>
              </torsional>
              <ode/>
            </friction>
          </surface>
        </collision>
        <visual name='visual'>
          <geometry>
            <mesh>
              <uri>model://cessna/meshes/left_flap.dae</uri>
            </mesh>
          </geometry>
        </visual>
        <self_collide>0</self_collide>
        <enable_wind>0</enable_wind>
        <kinematic>0</kinematic>
      </link>
      <link name='right_aileron'>
        <inertial>
          <mass>2</mass>
          <inertia>
            <ixx>0.8434</ixx>
            <ixy>0</ixy>
            <iyy>0.0119</iyy>
            <ixz>0</ixz>
            <iyz>0</iyz>
            <izz>0.855</izz>
          </inertia>
          <pose>-1.65 -3.7 1.5 -0.05 -0 0.12</pose>
        </inertial>
        <collision name='collision'>
          <geometry>
            <mesh>
              <uri>model://cessna/meshes/right_aileron.dae</uri>
            </mesh>
          </geometry>
          <max_contacts>10</max_contacts>
          <surface>
            <contact>
              <ode/>
            </contact>
            <bounce/>
            <friction>
              <torsional>
                <ode/>
              </torsional>
              <ode/>
            </friction>
          </surface>
        </collision>
        <visual name='visual'>
          <geometry>
            <mesh>
              <uri>model://cessna/meshes/right_aileron.dae</uri>
            </mesh>
          </geometry>
        </visual>
        <self_collide>0</self_collide>
        <enable_wind>0</enable_wind>
        <kinematic>0</kinematic>
      </link>
      <link name='right_flap'>
        <inertial>
          <mass>2</mass>
          <inertia>
            <ixx>0.6747</ixx>
            <ixy>0</ixy>
            <iyy>0.0242</iyy>
            <ixz>0</ixz>
            <iyz>0</iyz>
            <izz>0.6962</izz>
          </inertia>
          <pose>-1.8 -1.55 1.43 -0.02 0 0</pose>
        </inertial>
        <collision name='collision'>
          <geometry>
            <mesh>
              <uri>model://cessna/meshes/right_flap.dae</uri>
            </mesh>
          </geometry>
          <max_contacts>10</max_contacts>
          <surface>
            <contact>
              <ode/>
            </contact>
            <bounce/>
            <friction>
              <torsional>
                <ode/>
              </torsional>
              <ode/>
            </friction>
          </surface>
        </collision>
        <visual name='visual'>
          <geometry>
            <mesh>
              <uri>model://cessna/meshes/right_flap.dae</uri>
            </mesh>
          </geometry>
        </visual>
        <self_collide>0</self_collide>
        <enable_wind>0</enable_wind>
        <kinematic>0</kinematic>
      </link>
      <link name='elevators'>
        <inertial>
          <mass>2</mass>
          <inertia>
            <ixx>1.5008</ixx>
            <ixy>0</ixy>
            <iyy>0.0274</iyy>
            <ixz>0</ixz>
            <iyz>0</iyz>
            <izz>1.5266</izz>
          </inertia>
          <pose>-5.75 0 0.57 0 -0 0</pose>
        </inertial>
        <collision name='collision'>
          <geometry>
            <mesh>
              <uri>model://cessna/meshes/elevators.dae</uri>
            </mesh>
          </geometry>
          <max_contacts>10</max_contacts>
          <surface>
            <contact>
              <ode/>
            </contact>
            <bounce/>
            <friction>
              <torsional>
                <ode/>
              </torsional>
              <ode/>
            </friction>
          </surface>
        </collision>
        <visual name='visual'>
          <geometry>
            <mesh>
              <uri>model://cessna/meshes/elevators.dae</uri>
            </mesh>
          </geometry>
        </visual>
        <self_collide>0</self_collide>
        <enable_wind>0</enable_wind>
        <kinematic>0</kinematic>
      </link>
      <link name='rudder'>
        <inertial>
          <mass>2</mass>
          <inertia>
            <ixx>0.4708</ixx>
            <ixy>0</ixy>
            <iyy>0.5208</iyy>
            <ixz>0</ixz>
            <iyz>0</iyz>
            <izz>0.0508</izz>
          </inertia>
          <pose>-6.1 0 1.3 0 -0.35 0</pose>
        </inertial>
        <collision name='collision'>
          <geometry>
            <mesh>
              <uri>model://cessna/meshes/rudder.dae</uri>
            </mesh>
          </geometry>
          <max_contacts>10</max_contacts>
          <surface>
            <contact>
              <ode/>
            </contact>
            <bounce/>
            <friction>
              <torsional>
                <ode/>
              </torsional>
              <ode/>
            </friction>
          </surface>
        </collision>
        <visual name='visual'>
          <geometry>
            <mesh>
              <uri>model://cessna/meshes/rudder.dae</uri>
            </mesh>
          </geometry>
        </visual>
        <self_collide>0</self_collide>
        <enable_wind>0</enable_wind>
        <kinematic>0</kinematic>
      </link>
      <link name='propeller'>
        <pose>1.79 0 0.855 0 -0 0</pose>
        <inertial>
          <mass>18.37</mass>
          <inertia>
            <ixx>7.5067</ixx>
            <ixy>0</ixy>
            <iyy>7.515</iyy>
            <ixz>0</ixz>
            <iyz>0</iyz>
            <izz>0.068275</izz>
          </inertia>
          <pose>-0.35 0 0 0 -0 0</pose>
        </inertial>
        <collision name='collision'>
          <geometry>
            <mesh>
              <uri>model://cessna/meshes/cessna_prop.dae</uri>
            </mesh>
          </geometry>
          <max_contacts>10</max_contacts>
          <surface>
            <contact>
              <ode/>
            </contact>
            <bounce/>
            <friction>
              <torsional>
                <ode/>
              </torsional>
              <ode/>
            </friction>
          </surface>
        </collision>
        <visual name='visual'>
          <geometry>
            <mesh>
              <uri>model://cessna/meshes/cessna_prop.dae</uri>
            </mesh>
          </geometry>
        </visual>
        <self_collide>0</self_collide>
        <enable_wind>0</enable_wind>
        <kinematic>0</kinematic>
      </link>
      <link name='front_wheel'>
        <inertial>
          <mass>2</mass>
          <inertia>
            <ixx>0.01786</ixx>
            <ixy>0</ixy>
            <iyy>0.01786</iyy>
            <ixz>0</ixz>
            <iyz>0</iyz>
            <izz>0.0324</izz>
          </inertia>
          <pose>0.712 0 -0.313 1.57079 -0 0</pose>
        </inertial>
        <collision name='collision'>
          <pose>0.712 0 -0.313 1.57079 -0 0</pose>
          <geometry>
            <cylinder>
              <radius>0.18</radius>
              <length>0.1</length>
            </cylinder>
          </geometry>
          <surface>
            <friction>
              <ode>
                <mu>0.3</mu>
                <mu2>0.3</mu2>
              </ode>
              <torsional>
                <ode/>
              </torsional>
            </friction>
            <contact>
              <ode>
                <max_vel>0.1</max_vel>
                <min_depth>0.001</min_depth>
              </ode>
            </contact>
            <bounce/>
          </surface>
          <max_contacts>10</max_contacts>
        </collision>
        <visual name='visual'>
          <geometry>
            <mesh>
              <uri>model://cessna/meshes/cessna_front_wheel.dae</uri>
            </mesh>
          </geometry>
        </visual>
        <self_collide>0</self_collide>
        <enable_wind>0</enable_wind>
        <kinematic>0</kinematic>
      </link>
      <link name='rear_left_wheel'>
        <inertial>
          <mass>2</mass>
          <inertia>
            <ixx>0.035516</ixx>
            <ixy>0</ixy>
            <iyy>0.035516</iyy>
            <ixz>0</ixz>
            <iyz>0</iyz>
            <izz>0.0625</izz>
          </inertia>
          <pose>-1 1.27 -0.25 1.57079 -0 0</pose>
        </inertial>
        <collision name='collision'>
          <pose>-1 1.27 -0.25 1.57079 -0 0</pose>
          <geometry>
            <cylinder>
              <radius>0.25</radius>
              <length>0.16</length>
            </cylinder>
          </geometry>
          <surface>
            <friction>
              <ode>
                <mu>0.3</mu>
                <mu2>0.3</mu2>
              </ode>
              <torsional>
                <ode/>
              </torsional>
            </friction>
            <contact>
              <ode>
                <max_vel>0.1</max_vel>
                <min_depth>0.001</min_depth>
              </ode>
            </contact>
            <bounce/>
          </surface>
          <max_contacts>10</max_contacts>
        </collision>
        <visual name='visual'>
          <geometry>
            <mesh>
              <uri>model://cessna/meshes/cessna_rear_left_wheel.dae</uri>
            </mesh>
          </geometry>
        </visual>
        <self_collide>0</self_collide>
        <enable_wind>0</enable_wind>
        <kinematic>0</kinematic>
      </link>
      <link name='rear_right_wheel'>
        <inertial>
          <mass>2</mass>
          <inertia>
            <ixx>0.035516</ixx>
            <ixy>0</ixy>
            <iyy>0.035516</iyy>
            <ixz>0</ixz>
            <iyz>0</iyz>
            <izz>0.0625</izz>
          </inertia>
          <pose>-1 -1.27 -0.25 1.57079 -0 0</pose>
        </inertial>
        <collision name='collision'>
          <pose>-1 -1.27 -0.25 1.57079 -0 0</pose>
          <geometry>
            <cylinder>
              <radius>0.25</radius>
              <length>0.16</length>
            </cylinder>
          </geometry>
          <surface>
            <friction>
              <ode>
                <mu>0.3</mu>
                <mu2>0.3</mu2>
              </ode>
              <torsional>
                <ode/>
              </torsional>
            </friction>
            <contact>
              <ode>
                <max_vel>0.1</max_vel>
                <min_depth>0.001</min_depth>
              </ode>
            </contact>
            <bounce/>
          </surface>
          <max_contacts>10</max_contacts>
        </collision>
        <visual name='visual'>
          <geometry>
            <mesh>
              <uri>model://cessna/meshes/cessna_rear_right_wheel.dae</uri>
            </mesh>
          </geometry>
        </visual>
        <self_collide>0</self_collide>
        <enable_wind>0</enable_wind>
        <kinematic>0</kinematic>
      </link>
      <joint name='left_flap_joint' type='revolute'>
        <parent>body</parent>
        <child>left_flap</child>
        <pose>-1.6 1.55 1.43 0.02 -0 0</pose>
        <axis>
          <xyz>0 1 0</xyz>
          <limit>
            <lower>-0.53</lower>
            <upper>0.53</upper>
            <effort>-1</effort>
            <velocity>-1</velocity>
          </limit>
          <dynamics>
            <damping>1</damping>
            <spring_reference>0</spring_reference>
            <spring_stiffness>0</spring_stiffness>
          </dynamics>
        </axis>
        <physics>
          <ode>
            <implicit_spring_damper>1</implicit_spring_damper>
            <limit>
              <cfm>0</cfm>
              <erp>0.2</erp>
            </limit>
          </ode>
        </physics>
      </joint>
      <joint name='left_aileron_joint' type='revolute'>
        <parent>body</parent>
        <child>left_aileron</child>
        <pose>-1.45 3.7 1.5 0.05 -0 -0.12</pose>
        <axis>
          <xyz>0 1 0</xyz>
          <limit>
            <lower>-0.53</lower>
            <upper>0.53</upper>
            <effort>-1</effort>
            <velocity>-1</velocity>
          </limit>
          <dynamics>
            <damping>1</damping>
            <spring_reference>0</spring_reference>
            <spring_stiffness>0</spring_stiffness>
          </dynamics>
        </axis>
        <physics>
          <ode>
            <implicit_spring_damper>1</implicit_spring_damper>
            <limit>
              <cfm>0</cfm>
              <erp>0.2</erp>
            </limit>
          </ode>
        </physics>
      </joint>
      <joint name='right_flap_joint' type='revolute'>
        <parent>body</parent>
        <child>right_flap</child>
        <pose>-1.6 -1.55 1.43 -0.02 0 0</pose>
        <axis>
          <xyz>0 1 0</xyz>
          <limit>
            <lower>-0.53</lower>
            <upper>0.53</upper>
            <effort>-1</effort>
            <velocity>-1</velocity>
          </limit>
          <dynamics>
            <damping>1</damping>
            <spring_reference>0</spring_reference>
            <spring_stiffness>0</spring_stiffness>
          </dynamics>
        </axis>
        <physics>
          <ode>
            <implicit_spring_damper>1</implicit_spring_damper>
            <limit>
              <cfm>0</cfm>
              <erp>0.2</erp>
            </limit>
          </ode>
        </physics>
      </joint>
      <joint name='right_aileron_joint' type='revolute'>
        <parent>body</parent>
        <child>right_aileron</child>
        <pose>-1.45 -3.7 1.5 -0.05 -0 0.12</pose>
        <axis>
          <xyz>0 1 0</xyz>
          <limit>
            <lower>-0.53</lower>
            <upper>0.53</upper>
            <effort>-1</effort>
            <velocity>-1</velocity>
          </limit>
          <dynamics>
            <damping>1</damping>
            <spring_reference>0</spring_reference>
            <spring_stiffness>0</spring_stiffness>
          </dynamics>
        </axis>
        <physics>
          <ode>
            <implicit_spring_damper>1</implicit_spring_damper>
            <limit>
              <cfm>0</cfm>
              <erp>0.2</erp>
            </limit>
          </ode>
        </physics>
      </joint>
      <joint name='elevators_joint' type='revolute'>
        <parent>body</parent>
        <child>elevators</child>
        <pose>-5.55 0 0.57 0 -0 0</pose>
        <axis>
          <xyz>0 1 0</xyz>
          <limit>
            <lower>-0.53</lower>
            <upper>0.53</upper>
            <effort>-1</effort>
            <velocity>-1</velocity>
          </limit>
          <dynamics>
            <damping>1</damping>
            <spring_reference>0</spring_reference>
            <spring_stiffness>0</spring_stiffness>
          </dynamics>
        </axis>
        <physics>
          <ode>
            <implicit_spring_damper>1</implicit_spring_damper>
            <limit>
              <cfm>0</cfm>
              <erp>0.2</erp>
            </limit>
          </ode>
        </physics>
      </joint>
      <joint name='rudder_joint' type='revolute'>
        <parent>body</parent>
        <child>rudder</child>
        <pose>-5.9 0 1.3 0 -0.35 0</pose>
        <axis>
          <xyz>0 0 1</xyz>
          <limit>
            <lower>-0.53</lower>
            <upper>0.53</upper>
            <effort>-1</effort>
            <velocity>-1</velocity>
          </limit>
          <dynamics>
            <damping>1</damping>
            <spring_reference>0</spring_reference>
            <spring_stiffness>0</spring_stiffness>
          </dynamics>
        </axis>
        <physics>
          <ode>
            <implicit_spring_damper>1</implicit_spring_damper>
            <limit>
              <cfm>0</cfm>
              <erp>0.2</erp>
            </limit>
          </ode>
        </physics>
      </joint>
      <joint name='propeller_joint' type='revolute'>
        <parent>body</parent>
        <child>propeller</child>
        <axis>
          <xyz>1 0 0</xyz>
          <limit>
            <lower>-1e+12</lower>
            <upper>1e+12</upper>
            <effort>-1</effort>
            <velocity>-1</velocity>
          </limit>
          <dynamics>
            <damping>0.001</damping>
            <spring_reference>0</spring_reference>
            <spring_stiffness>0</spring_stiffness>
          </dynamics>
        </axis>
        <physics>
          <ode>
            <implicit_spring_damper>1</implicit_spring_damper>
            <limit>
              <cfm>0</cfm>
              <erp>0.2</erp>
            </limit>
          </ode>
        </physics>
      </joint>
      <joint name='front_wheel_joint' type='revolute'>
        <parent>body</parent>
        <child>front_wheel</child>
        <pose>0.712 0 -0.313 0 -0 0</pose>
        <axis>
          <xyz>0 1 0</xyz>
          <limit>
            <lower>-1e+12</lower>
            <upper>1e+12</upper>
            <effort>-1</effort>
            <velocity>-1</velocity>
          </limit>
          <dynamics>
            <damping>0.01</damping>
            <spring_reference>0</spring_reference>
            <spring_stiffness>0</spring_stiffness>
          </dynamics>
        </axis>
        <physics>
          <ode>
            <implicit_spring_damper>1</implicit_spring_damper>
            <limit>
              <cfm>0</cfm>
              <erp>0.2</erp>
            </limit>
          </ode>
        </physics>
      </joint>
      <joint name='rear_left_wheel_joint' type='revolute'>
        <parent>body</parent>
        <child>rear_left_wheel</child>
        <pose>-1 -1.27 -0.25 0 -0 0</pose>
        <axis>
          <xyz>0 1 0</xyz>
          <limit>
            <lower>-1e+12</lower>
            <upper>1e+12</upper>
            <effort>-1</effort>
            <velocity>-1</velocity>
          </limit>
          <dynamics>
            <damping>0.01</damping>
            <spring_reference>0</spring_reference>
            <spring_stiffness>0</spring_stiffness>
          </dynamics>
        </axis>
        <physics>
          <ode>
            <implicit_spring_damper>1</implicit_spring_damper>
            <limit>
              <cfm>0</cfm>
              <erp>0.2</erp>
            </limit>
          </ode>
        </physics>
      </joint>
      <joint name='rear_right_wheel_joint' type='revolute'>
        <parent>body</parent>
        <child>rear_right_wheel</child>
        <pose>-1 1.27 -0.25 0 -0 0</pose>
        <axis>
          <xyz>0 1 0</xyz>
          <limit>
            <lower>-1e+12</lower>
            <upper>1e+12</upper>
            <effort>-1</effort>
            <velocity>-1</velocity>
          </limit>
          <dynamics>
            <damping>0.01</damping>
            <spring_reference>0</spring_reference>
            <spring_stiffness>0</spring_stiffness>
          </dynamics>
        </axis>
        <physics>
          <ode>
            <implicit_spring_damper>1</implicit_spring_damper>
            <limit>
              <cfm>0</cfm>
              <erp>0.2</erp>
            </limit>
          </ode>
        </physics>
      </joint>
    </model>
    <model name='coke_can'>
      <link name='link'>
        <inertial>
          <pose>0 0 0.06 0 -0 0</pose>
          <mass>0.39</mass>
          <inertia>
            <ixx>0.00055575</ixx>
            <ixy>0</ixy>
            <ixz>0</ixz>
            <iyy>0.00055575</iyy>
            <iyz>0</iyz>
            <izz>0.0001755</izz>
          </inertia>
        </inertial>
        <collision name='collision'>
          <pose>0.003937 0.004724 -0.18 0 -0 0</pose>
          <geometry>
            <mesh>
              <uri>model://coke_can/meshes/coke_can.dae</uri>
            </mesh>
          </geometry>
          <surface>
            <friction>
              <ode>
                <mu>1</mu>
                <mu2>1</mu2>
              </ode>
              <torsional>
                <ode/>
              </torsional>
            </friction>
            <contact>
              <ode>
                <kp>1e+07</kp>
                <kd>1</kd>
                <min_depth>0.001</min_depth>
                <max_vel>0.1</max_vel>
              </ode>
            </contact>
            <bounce/>
          </surface>
          <max_contacts>10</max_contacts>
        </collision>
        <visual name='visual'>
          <pose>0.003937 0.004724 -0.18 0 -0 0</pose>
          <geometry>
            <mesh>
              <uri>model://coke_can/meshes/coke_can.dae</uri>
            </mesh>
          </geometry>
        </visual>
        <self_collide>0</self_collide>
        <enable_wind>0</enable_wind>
        <kinematic>0</kinematic>
      </link>
      <pose>3.60717 0.358804 0 0 -0 0</pose>
    </model>
    <model name='fountain'>
      <static>1</static>
      <link name='link'>
        <collision name='collision'>
          <geometry>
            <mesh>
              <uri>model://fountain/meshes/fountain.dae</uri>
            </mesh>
          </geometry>
          <max_contacts>10</max_contacts>
          <surface>
            <contact>
              <ode/>
            </contact>
            <bounce/>
            <friction>
              <torsional>
                <ode/>
              </torsional>
              <ode/>
            </friction>
          </surface>
        </collision>
        <visual name='visual'>
          <geometry>
            <mesh>
              <uri>model://fountain/meshes/fountain.dae</uri>
            </mesh>
          </geometry>
        </visual>
        <self_collide>0</self_collide>
        <enable_wind>0</enable_wind>
        <kinematic>0</kinematic>
      </link>
      <pose>4.7562 -4.99313 0 0 -0 0</pose>
    </model>
    <model name='standpipe'>
      <static>1</static>
      <link name='standpipe'>
        <pose>0 0 0.1 0 1.57078 0</pose>
        <collision name='collision_stopper'>
          <pose>0 0 0.22 0 -0 0</pose>
          <geometry>
            <cylinder>
              <radius>0.069</radius>
              <length>0.1</length>
            </cylinder>
          </geometry>
          <surface>
            <friction>
              <ode>
                <mu>0.5</mu>
                <mu2>0.5</mu2>
              </ode>
              <torsional>
                <ode/>
              </torsional>
            </friction>
            <contact>
              <ode/>
            </contact>
            <bounce/>
          </surface>
          <max_contacts>10</max_contacts>
        </collision>
        <collision name='collision'>
          <pose>0 0 0.15 0 -0 0</pose>
          <geometry>
            <mesh>
              <uri>model://standpipe/meshes/standpipe.dae</uri>
            </mesh>
          </geometry>
          <surface>
            <friction>
              <ode>
                <mu>0.5</mu>
                <mu2>0.5</mu2>
              </ode>
              <torsional>
                <ode/>
              </torsional>
            </friction>
            <contact>
              <ode/>
            </contact>
            <bounce/>
          </surface>
          <max_contacts>10</max_contacts>
        </collision>
        <visual name='visual'>
          <pose>0 0 0.15 0 -0 0</pose>
          <geometry>
            <mesh>
              <uri>model://standpipe/meshes/standpipe.dae</uri>
            </mesh>
          </geometry>
        </visual>
        <self_collide>0</self_collide>
        <enable_wind>0</enable_wind>
        <kinematic>0</kinematic>
      </link>
      <pose>-0.652705 5.35755 0 0 -0 0</pose>
    </model>
    <model name='ambulance_0'>
      <static>1</static>
      <link name='link'>
        <collision name='collision'>
          <geometry>
            <mesh>
              <scale>0.0254 0.0254 0.0254</scale>
              <uri>model://ambulance/meshes/ambulance.obj</uri>
            </mesh>
          </geometry>
          <max_contacts>10</max_contacts>
          <surface>
            <contact>
              <ode/>
            </contact>
            <bounce/>
            <friction>
              <torsional>
                <ode/>
              </torsional>
              <ode/>
            </friction>
          </surface>
        </collision>
        <visual name='visual'>
          <geometry>
            <mesh>
              <scale>0.0254 0.0254 0.0254</scale>
              <uri>model://ambulance/meshes/ambulance.obj</uri>
            </mesh>
          </geometry>
        </visual>
        <self_collide>0</self_collide>
        <enable_wind>0</enable_wind>
        <kinematic>0</kinematic>
      </link>
      <pose>12.2307 5.87018 0 0 -0 0</pose>
    </model>
    <state world_name='default'>
      <sim_time>1408 227000000</sim_time>
      <real_time>1481 893612732</real_time>
      <wall_time>1693438570 124451010</wall_time>
      <iterations>1408227</iterations>
      <model name='Lamp Post'>
        <pose>2.16286 8.12859 0 0 -0 0</pose>
        <scale>1 1 1</scale>
        <link name='link'>
          <pose>2.16286 8.12859 0 0 -0 0</pose>
          <velocity>0 0 0 0 -0 0</velocity>
          <acceleration>0 0 0 0 -0 0</acceleration>
          <wrench>0 0 0 0 -0 0</wrench>
        </link>
      </model>
      <model name='ambulance'>
        <pose>6.51401 4.62614 0 0 -0 0</pose>
        <scale>1 1 1</scale>
        <link name='link'>
          <pose>6.51401 4.62614 0 0 -0 0</pose>
          <velocity>0 0 0 0 -0 0</velocity>
          <acceleration>0 0 0 0 -0 0</acceleration>
          <wrench>0 0 0 0 -0 0</wrench>
        </link>
      </model>
      <model name='ambulance_0'>
        <pose>12.2307 5.87018 0 0 -0 0</pose>
        <scale>1 1 1</scale>
        <link name='link'>
          <pose>12.2307 5.87018 0 0 -0 0</pose>
          <velocity>0 0 0 0 -0 0</velocity>
          <acceleration>0 0 0 0 -0 0</acceleration>
          <wrench>0 0 0 0 -0 0</wrench>
        </link>
      </model>
      <model name='car_wheel'>
        <pose>3.71293 3.67668 -0.004165 0 9.2e-05 0</pose>
        <scale>1 1 1</scale>
        <link name='link'>
          <pose>3.71295 3.67668 0.212655 0 1.57079 0</pose>
          <velocity>0 0 0 0 -0 0</velocity>
          <acceleration>0 0 0 0 -0 0</acceleration>
          <wrench>0 0 0 0 -0 0</wrench>
        </link>
      </model>
      <model name='cart_soft_suspension'>
        <pose>4.57403 5.77208 0.037475 5e-05 5.9e-05 -0.049979</pose>
        <scale>1 1 1</scale>
        <link name='chassis'>
          <pose>4.57404 5.77208 0.187475 5e-05 5.9e-05 -0.049979</pose>
          <velocity>-0.001988 0.002513 -0.003271 0.046231 -0.032738 -0.009415</velocity>
          <acceleration>-0.232534 0.8237 -3.3778 -1.22992 0.744771 -0.741021</acceleration>
          <wrench>-2.32534 8.237 -33.778 0 -0 0</wrench>
        </link>
        <link name='susp_front_left'>
          <pose>5.0883 6.04473 0.150021 0.000587 -0.000155 -0.049938</pose>
          <velocity>0.004466 -0.005509 0.00146 0.033991 -0.02409 -0.007699</velocity>
          <acceleration>2.93453 -0.576701 0.102015 1.63962 0.259395 -2.97239</acceleration>
          <wrench>1.46727 -0.28835 0.051008 0 -0 0</wrench>
        </link>
        <link name='susp_front_right'>
          <pose>5.05854 5.44945 0.150015 -0.000407 -0.000185 -0.049714</pose>
          <velocity>-0.014837 -0.009155 -0.002673 0.065607 -0.027422 -0.040268</velocity>
          <acceleration>-3.94704 0.947071 0.123479 0.415681 -0.838117 -1.68921</acceleration>
          <wrench>-1.97352 0.473535 0.06174 0 -0 0</wrench>
        </link>
        <link name='susp_rear_left'>
          <pose>4.08957 6.0947 0.150004 0.00027 0.000399 -0.050235</pose>
          <velocity>-0.005977 -0.005188 0.000154 -0.010065 -0.117148 -0.004053</velocity>
          <acceleration>-3.18781 -4.11415 -9.6969 -2.83916 -0.131997 2.55564</acceleration>
          <wrench>-1.5939 -2.05708 -4.84845 0 -0 0</wrench>
        </link>
        <link name='susp_rear_right'>
          <pose>4.05977 5.49939 0.149993 -8.1e-05 0.000338 -0.050169</pose>
          <velocity>0.014701 -0.021787 -0.013554 0.070744 -0.101955 0.086967</velocity>
          <acceleration>6.74785 0.528201 -9.8045 -1.00737 1.21011 2.25394</acceleration>
          <wrench>3.37393 0.264101 -4.90225 0 -0 0</wrench>
        </link>
        <link name='wheel_front_left'>
          <pose>5.0883 6.04474 0.150021 -1.56677 1.43389 -0.045951</pose>
          <velocity>0.004459 -0.005579 0.001451 0.036807 0.027515 -0.00825</velocity>
          <acceleration>2.94257 -0.565012 0.097774 0.066374 0.999625 -0.074132</acceleration>
          <wrench>1.47128 -0.282506 0.048887 0 -0 0</wrench>
        </link>
        <link name='wheel_front_right'>
          <pose>5.05854 5.44945 0.150015 1.57154 1.03292 3.09251</pose>
          <velocity>-0.01485 -0.009006 -0.002663 0.060735 -0.088323 -0.040109</velocity>
          <acceleration>-3.96682 0.889564 0.127379 1.29092 -1.55877 -0.544989</acceleration>
          <wrench>-1.98341 0.444782 0.063689 0 -0 0</wrench>
        </link>
        <link name='wheel_rear_left'>
          <pose>4.08957 6.0947 0.150005 1.57047 1.16689 3.09104</pose>
          <velocity>-0.005936 -0.004961 -7.3e-05 0.028051 -0.019984 -0.001436</velocity>
          <acceleration>-3.17116 -4.21001 -9.90239 -2.07755 -1.1606 -0.124036</acceleration>
          <wrench>-1.58558 -2.10501 -4.95119 0 -0 0</wrench>
        </link>
        <link name='wheel_rear_right'>
          <pose>4.05977 5.49939 0.149993 1.5709 0.721751 3.0915</pose>
          <velocity>0.014703 -0.021805 -0.013565 0.073205 -0.017942 0.086034</velocity>
          <acceleration>6.72201 0.559761 -9.80163 -2.53316 0.453728 1.47527</acceleration>
          <wrench>3.361 0.279881 -4.90082 0 -0 0</wrench>
        </link>
      </model>
      <model name='cessna_c172'>
        <pose>-2.64945 -11.8341 0.492465 0.000423 -0.000574 -0.018757</pose>
        <scale>1 1 1</scale>
        <link name='body'>
          <pose>-2.64945 -11.8341 0.492465 0.000423 -0.000574 -0.018757</pose>
          <velocity>-1.2e-05 8.5e-05 -0.000335 0.002316 -0.001053 0.001353</velocity>
          <acceleration>0.007122 0.411244 0.85681 -0.001294 -0.166853 0.012452</acceleration>
          <wrench>4.84585 279.806 582.964 0 -0 0</wrench>
        </link>
        <link name='elevators'>
          <pose>-3.12431 -11.8265 3.37611 0.000491 -0.530575 -0.019006</pose>
          <velocity>-0.001864 -0.007257 -0.003422 0.002326 -0.000537 0.001354</velocity>
          <acceleration>0.093551 0.339234 -0.131289 -0.007184 -0.259307 0.012949</acceleration>
          <wrench>0.187103 0.678468 -0.262578 0 -0 0</wrench>
        </link>
        <link name='front_wheel'>
          <pose>-2.70335 -11.833 0.314197 0.000184 -0.240764 -0.018803</pose>
          <velocity>0.000697 0.009297 0.006273 -0.034205 0.002527 0.001545</velocity>
          <acceleration>0.355706 10.6635 -5.92057 -1.08485 0.198739 -2.40496</acceleration>
          <wrench>0.711411 21.3269 -11.8411 0 -0 0</wrench>
        </link>
        <link name='left_aileron'>
          <pose>-2.25122 -11.9475 1.62445 -0.061574 -0.526591 -0.029415</pose>
          <velocity>-0.001548 -0.001578 -0.007127 0.002728 0.001897 0.001504</velocity>
          <acceleration>-0.049609 0.391073 0.445598 -0.100866 -0.776086 -0.019119</acceleration>
          <wrench>-0.099217 0.782146 0.891196 0 -0 0</wrench>
        </link>
        <link name='left_flap'>
          <pose>-2.1629 -11.8637 1.49329 0.003678 -0.530454 -0.030726</pose>
          <velocity>-0.00145 -0.001519 -0.002179 0.002337 2.7e-05 0.001375</velocity>
          <acceleration>-0.051515 0.392617 0.528285 -0.013433 -0.438144 0.006581</acceleration>
          <wrench>-0.103031 0.785234 1.05657 0 -0 0</wrench>
        </link>
        <link name='propeller'>
          <pose>-0.860259 -11.8681 1.34849 0.030747 -0.000574 -0.018758</pose>
          <velocity>-0.000867 0.000335 0.001464 0.00028 -0.000989 0.001185</velocity>
          <acceleration>0.022227 0.070923 1.09956 -0.001871 -0.113825 -0.04016</acceleration>
          <wrench>0.408318 1.30285 20.1988 0 -0 0</wrench>
        </link>
        <link name='rear_left_wheel'>
          <pose>-2.75154 -11.832 0.75666 -0.000258 -0.268744 -0.018692</pose>
          <velocity>-0.002541 -0.000117 0.011612 0.001309 -0.005851 0.00138</velocity>
          <acceleration>-0.045187 0.299954 0.016799 -1.17982 -0.17351 0.007419</acceleration>
          <wrench>-0.090374 0.599907 0.033599 0 -0 0</wrench>
        </link>
        <link name='rear_right_wheel'>
          <pose>-2.88279 -11.8311 0.941618 0.002443 -0.487348 -0.019898</pose>
          <velocity>0.005463 -0.001703 0.001901 0.002824 0.007449 0.001323</velocity>
          <acceleration>-0.144167 0.315121 0.012977 -1.23439 -0.579115 0.037792</acceleration>
          <wrench>-0.288334 0.630243 0.025955 0 -0 0</wrench>
        </link>
        <link name='right_aileron'>
          <pose>-2.24727 -11.7368 1.62455 0.062553 -0.526604 -0.008591</pose>
          <velocity>-0.001994 -0.002491 -0.00838 0.001936 0.002698 0.001166</velocity>
          <acceleration>0.083928 0.39448 0.563548 0.105143 -1.47042 0.076534</acceleration>
          <wrench>0.167856 0.788959 1.1271 0 -0 0</wrench>
        </link>
        <link name='right_flap'>
          <pose>-2.16215 -11.8237 1.49333 -0.002696 -0.530475 -0.007284</pose>
          <velocity>-0.002627 -0.001704 -0.007992 0.00239 0.002854 0.001277</velocity>
          <acceleration>0.062789 0.386209 0.438533 -0.042742 -1.23782 0.032544</acceleration>
          <wrench>0.125577 0.772419 0.877065 0 -0 0</wrench>
        </link>
        <link name='rudder'>
          <pose>-2.64983 -11.8527 0.492445 0.001675 -0.00057 -0.022181</pose>
          <velocity>-0.000609 -0.028097 -0.00041 0.004216 -0.001089 -0.003841</velocity>
          <acceleration>-0.060029 0.124325 -0.153417 -0.384371 -0.149591 1.0622</acceleration>
          <wrench>-0.120057 0.24865 -0.306835 0 -0 0</wrench>
        </link>
      </model>
      <model name='coke_can'>
        <pose>3.57031 0.369349 0.048121 -0.32592 -0.27799 0.859365</pose>
        <scale>1 1 1</scale>
        <link name='link'>
          <pose>3.57031 0.369349 0.048121 -0.32592 -0.27799 0.859365</pose>
          <velocity>6.2e-05 1.3e-05 -0.000415 -0.002444 0.00118 0.001644</velocity>
          <acceleration>0.125461 0.105424 -0.387086 2.50376 1.21968 -2.81307</acceleration>
          <wrench>0.04893 0.041116 -0.150964 0 -0 0</wrench>
        </link>
      </model>
      <model name='euro_pallet'>
        <pose>0.601919 4.90707 0.072 0 0 -0.013016</pose>
        <scale>1 1 1</scale>
        <link name='link'>
          <pose>0.601919 4.90707 0.072 0 0 -0.013016</pose>
          <velocity>0 0 0 0 -0 0</velocity>
          <acceleration>-2.37803 -0.035389 11.3107 -2.88537 -1.5409 3.14159</acceleration>
          <wrench>-47.5607 -0.707786 226.215 0 -0 0</wrench>
        </link>
      </model>
      <model name='fountain'>
        <pose>4.7562 -4.99313 0 0 -0 0</pose>
        <scale>1 1 1</scale>
        <link name='link'>
          <pose>4.7562 -4.99313 0 0 -0 0</pose>
          <velocity>0 0 0 0 -0 0</velocity>
          <acceleration>0 0 0 0 -0 0</acceleration>
          <wrench>0 0 0 0 -0 0</wrench>
        </link>
      </model>
      <model name='gazebo'>
        <pose>10.1608 -8.0485 0 0 -0 0</pose>
        <scale>1 1 1</scale>
        <link name='link'>
          <pose>10.1608 -8.0485 0 0 -0 0</pose>
          <velocity>0 0 0 0 -0 0</velocity>
          <acceleration>0 0 0 0 -0 0</acceleration>
          <wrench>0 0 0 0 -0 0</wrench>
        </link>
      </model>
      <model name='ground_plane'>
        <pose>0 0 0 0 -0 0</pose>
        <scale>1 1 1</scale>
        <link name='link'>
          <pose>0 0 0 0 -0 0</pose>
          <velocity>0 0 0 0 -0 0</velocity>
          <acceleration>0 0 0 0 -0 0</acceleration>
          <wrench>0 0 0 0 -0 0</wrench>
        </link>
      </model>
      <model name='hatchback_red'>
        <pose>10.457 -1.13637 0 0 -0 0</pose>
        <scale>1 1 1</scale>
        <link name='link'>
          <pose>10.457 -1.13637 0 0 -0 0</pose>
          <velocity>0 0 0 0 -0 0</velocity>
          <acceleration>0 0 0 0 -0 0</acceleration>
          <wrench>0 0 0 0 -0 0</wrench>
        </link>
      </model>
      <model name='marble_1_5cm'>
        <pose>1.7705 2.85127 -0.001001 0 -0 0</pose>
        <scale>1 1 1</scale>
        <link name='link'>
          <pose>1.7705 2.85127 0.006499 0 -0 0</pose>
          <velocity>0 0 0 0 -0 0</velocity>
          <acceleration>0 0 -0 0 -0 0</acceleration>
          <wrench>0 0 -0 0 -0 0</wrench>
        </link>
      </model>
      <model name='marble_1_5cm_0'>
        <pose>3.48307 2.14789 -0.001001 0 -0 0</pose>
        <scale>1 1 1</scale>
        <link name='link'>
          <pose>3.48307 2.14789 0.006499 0 -0 0</pose>
          <velocity>0 0 0 0 -0 0</velocity>
          <acceleration>0 0 -0 0 -0 0</acceleration>
          <wrench>0 0 -0 0 -0 0</wrench>
        </link>
      </model>
      <model name='marble_1_5cm_1'>
        <pose>2.99077 1.38928 -0.001001 0 -0 0</pose>
        <scale>1 1 1</scale>
        <link name='link'>
          <pose>2.99077 1.38928 0.006499 0 -0 0</pose>
          <velocity>0 0 0 0 -0 0</velocity>
          <acceleration>0 0 -0 0 -0 0</acceleration>
          <wrench>0 0 -0 0 -0 0</wrench>
        </link>
      </model>
      <model name='mars_rover'>
        <pose>4.64474 -8.26488 0 0 -0 0</pose>
        <scale>1 1 1</scale>
        <link name='link'>
          <pose>4.64474 -8.26488 0 0 -0 0</pose>
          <velocity>0 0 0 0 -0 0</velocity>
          <acceleration>0 0 0 0 -0 0</acceleration>
          <wrench>0 0 0 0 -0 0</wrench>
        </link>
      </model>
      <model name='oak_tree'>
        <pose>5.77899 -12.5457 0 0 -0 0</pose>
        <scale>1 1 1</scale>
        <link name='link'>
          <pose>5.77899 -12.5457 0 0 -0 0</pose>
          <velocity>0 0 0 0 -0 0</velocity>
          <acceleration>0 0 0 0 -0 0</acceleration>
          <wrench>0 0 0 0 -0 0</wrench>
        </link>
      </model>
      <model name='person_standing'>
        <pose>10.5068 -6.54861 0.367923 0 0 -0.023079</pose>
        <scale>1 1 1</scale>
        <link name='link'>
          <pose>10.5068 -6.54861 0.367923 0 0 -0.023079</pose>
          <velocity>0 0 0 0 -0 0</velocity>
          <acceleration>0.362419 -0.595934 -0.073488 0.626914 0.381058 -0.000867</acceleration>
          <wrench>28.9935 -47.6747 -5.87906 0 -0 0</wrench>
        </link>
      </model>
      <model name='standpipe'>
        <pose>-0.652705 5.35755 0 0 -0 0</pose>
        <scale>1 1 1</scale>
        <link name='standpipe'>
          <pose>-0.652705 5.35755 0.1 0 1.57078 0</pose>
          <velocity>0 0 0 0 -0 0</velocity>
          <acceleration>0 0 0 0 -0 0</acceleration>
          <wrench>0 0 0 0 -0 0</wrench>
        </link>
      </model>
      <model name='wood_block_10_2_1cm'>
        <pose>3.77283 0.158259 0.011958 1.57081 0.010543 -0.004756</pose>
        <scale>1 1 1</scale>
        <link name='link'>
          <pose>3.7728 0.153259 0.011958 1.57081 0.010543 -0.004756</pose>
          <velocity>0.000647 0.000148 0.012846 -0.009666 0.049929 -0.000387</velocity>
          <acceleration>2.42001 0.099221 37.5028 1.14757 -1.0306 -3.03716</acceleration>
          <wrench>0.03025 0.00124 0.468785 0 -0 0</wrench>
        </link>
      </model>
      <model name='wood_block_10_2_1cm_0'>
        <pose>3.93478 0.5192 -0.001 0 -0 0</pose>
        <scale>1 1 1</scale>
        <link name='link'>
          <pose>3.93478 0.5192 0.004 0 -0 0</pose>
          <velocity>0 0 0 0 -0 0</velocity>
          <acceleration>-3e-06 -6.8e-05 1e-06 0.013504 -0.000665 0</acceleration>
          <wrench>-0 -1e-06 0 0 -0 0</wrench>
        </link>
      </model>
      <model name='wood_cube_10cm'>
        <pose>3.39986 1.53033 -0.001013 0 -0 0</pose>
        <scale>1 1 1</scale>
        <link name='link'>
          <pose>3.39986 1.53033 0.048987 0 -0 0</pose>
          <velocity>0 0 0 0 -0 0</velocity>
          <acceleration>-0 0 -0 0 -0 0</acceleration>
          <wrench>-0 0 -0 0 -0 0</wrench>
        </link>
      </model>
      <model name='wood_cube_10cm_0'>
        <pose>-4.08596 -194.191 0.048987 -1.12962 1.57079 3.14159</pose>
        <scale>1 1 1</scale>
        <link name='link'>
          <pose>-4.10731 -194.237 0.048987 -1.12962 1.57079 3.14159</pose>
          <velocity>0 0 0 0 -0 0</velocity>
          <acceleration>0 0 0 0 -0 0</acceleration>
          <wrench>0 0 0 0 -0 0</wrench>
        </link>
      </model>
      <model name='wood_cube_10cm_1'>
        <pose>3.64207 0.582951 0.048987 -1.16962 -1.57079 3.14159</pose>
        <scale>1 1 1</scale>
        <link name='link'>
          <pose>3.6616 0.53692 0.048987 -1.16962 -1.57079 3.14159</pose>
          <velocity>0 0 0 0 -0 0</velocity>
          <acceleration>-0 0 0 -0 -0 -0</acceleration>
          <wrench>-0 0 0 0 -0 0</wrench>
        </link>
      </model>
      <model name='wood_cube_10cm_2'>
        <pose>3.81254 -2.77196 0.048987 -1.5708 -0 -0.231807</pose>
        <scale>1 1 1</scale>
        <link name='link'>
          <pose>3.82403 -2.7233 0.048987 -1.5708 -0 -0.231807</pose>
          <velocity>0 0 0 0 -0 0</velocity>
          <acceleration>0 0 -0 0 -0 0</acceleration>
          <wrench>0 0 -0 0 -0 0</wrench>
        </link>
      </model>
      <model name='wooden_board'>
        <pose>4.64142 1.17578 -0.001007 0 -0 0</pose>
        <scale>1 1 1</scale>
        <link name='base'>
          <pose>4.64142 1.17578 0.004223 0 -0 0</pose>
          <velocity>0 0 0 0 -0 0</velocity>
          <acceleration>0 0 0 0 -0 0</acceleration>
          <wrench>0 0 0 0 -0 0</wrench>
        </link>
      </model>
      <model name='wooden_case'>
        <pose>3.8503 0.906314 -0.001057 0 -0.000428 0.007914</pose>
        <scale>1 1 1</scale>
        <link name='base'>
          <pose>3.85028 0.906314 0.022943 0 -0.000428 0.007914</pose>
          <velocity>0 0 7e-05 0 1.3e-05 0</velocity>
          <acceleration>0 -0 -0 0 -0 0</acceleration>
          <wrench>0 -0 -0 0 -0 0</wrench>
        </link>
        <link name='lid'>
          <pose>4.09405 0.908243 0.008487 0 5.4e-05 0.007913</pose>
          <velocity>0 -0 6.9e-05 0 -0 0</velocity>
          <acceleration>-0 -0 0 0 -0 0</acceleration>
          <wrench>-0 -0 0 0 -0 0</wrench>
        </link>
      </model>
      <model name='wooden_case_metal_peg'>
        <pose>3.59628 0.159658 0.017042 -5.3e-05 -0.420592 -0.005507</pose>
        <scale>1 1 1</scale>
        <link name='peg::link'>
          <pose>3.94645 0.373727 0.060581 -4.8e-05 0.103033 -0.005534</pose>
          <velocity>0.000145 2.2e-05 0.000862 -0.000187 -0.004819 -4.9e-05</velocity>
          <acceleration>1.00055 0.016414 6.11158 3.1402 0.929827 -2.63795</acceleration>
          <wrench>0.012107 0.000199 0.07395 0 -0 0</wrench>
        </link>
        <link name='wooden_case::base'>
          <pose>3.58649 0.159713 0.038951 -5.3e-05 -0.420592 -0.005507</pose>
          <velocity>6.7e-05 6e-06 -0.000429 -0.000155 0.00166 0</velocity>
          <acceleration>1.87109 -0.029383 -1.23524 -2.9378 -0.546379 3.12138</acceleration>
          <wrench>7.41447 -0.116434 -4.89483 0 -0 0</wrench>
        </link>
        <link name='wooden_case::lid'>
          <pose>3.81974 0.158423 0.032829 -4.8e-05 0.103032 -0.005533</pose>
          <velocity>0.000255 2.2e-05 0.000283 -0.000179 -0.00476 8e-06</velocity>
          <acceleration>1.79657 0.019484 2.39508 2.99563 0.75558 -3.09814</acceleration>
          <wrench>3.55494 0.038555 4.73925 0 -0 0</wrench>
        </link>
      </model>
      <light name='sun'>
        <pose>0 0 10 0 -0 0</pose>
      </light>
    </state>
    <gui fullscreen='0'>
      <camera name='user_camera'>
        <pose>-13.1131 -2.93535 20.3812 0 0.915643 -0.031805</pose>
        <view_controller>orbit</view_controller>
        <projection_type>perspective</projection_type>
      </camera>
    </gui>
  </world>
</sdf>
